[2020-06-15 11:41:42] - ERROR - Exception on /env [GET] - app 1892@log_exception
Traceback (most recent call last):
  File "C:\Users\accel\ProjectHome\phonogenesis\pyscript\venv\lib\site-packages\flask\app.py", line 2447, in wsgi_app
    response = self.full_dispatch_request()
  File "C:\Users\accel\ProjectHome\phonogenesis\pyscript\venv\lib\site-packages\flask\app.py", line 1952, in full_dispatch_request
    rv = self.handle_user_exception(e)
  File "C:\Users\accel\ProjectHome\phonogenesis\pyscript\venv\lib\site-packages\flask\app.py", line 1821, in handle_user_exception
    reraise(exc_type, exc_value, tb)
  File "C:\Users\accel\ProjectHome\phonogenesis\pyscript\venv\lib\site-packages\flask\_compat.py", line 39, in reraise
    raise value
  File "C:\Users\accel\ProjectHome\phonogenesis\pyscript\venv\lib\site-packages\flask\app.py", line 1950, in full_dispatch_request
    rv = self.dispatch_request()
  File "C:\Users\accel\ProjectHome\phonogenesis\pyscript\venv\lib\site-packages\flask\app.py", line 1936, in dispatch_request
    return self.view_functions[rule.endpoint](**req.view_args)
  File "C:\Users\accel\ProjectHome\phonogenesis\pyscript\app\routes.py", line 20, in environment_data
    return jsonify(DEFAULT_DATA)
  File "C:\Users\accel\ProjectHome\phonogenesis\pyscript\venv\lib\site-packages\flask\json\__init__.py", line 370, in jsonify
    dumps(data, indent=indent, separators=separators) + "\n",
  File "C:\Users\accel\ProjectHome\phonogenesis\pyscript\venv\lib\site-packages\flask\json\__init__.py", line 211, in dumps
    rv = _json.dumps(obj, **kwargs)
  File "C:\envbin\py37\lib\json\__init__.py", line 238, in dumps
    **kw).encode(obj)
  File "C:\envbin\py37\lib\json\encoder.py", line 199, in encode
    chunks = self.iterencode(o, _one_shot=True)
  File "C:\envbin\py37\lib\json\encoder.py", line 257, in iterencode
    return _iterencode(o, 0)
  File "C:\Users\accel\ProjectHome\phonogenesis\pyscript\venv\lib\site-packages\flask\json\__init__.py", line 100, in default
    return _json.JSONEncoder.default(self, o)
  File "C:\envbin\py37\lib\json\encoder.py", line 179, in default
    raise TypeError(f'Object of type {o.__class__.__name__} '
TypeError: Object of type Sound is not JSON serializable
[2020-06-15 12:09:39] - ERROR - Exception on /env [GET] - app 1892@log_exception
Traceback (most recent call last):
  File "C:\Users\accel\ProjectHome\phonogenesis\pyscript\venv\lib\site-packages\flask\app.py", line 2447, in wsgi_app
    response = self.full_dispatch_request()
  File "C:\Users\accel\ProjectHome\phonogenesis\pyscript\venv\lib\site-packages\flask\app.py", line 1952, in full_dispatch_request
    rv = self.handle_user_exception(e)
  File "C:\Users\accel\ProjectHome\phonogenesis\pyscript\venv\lib\site-packages\flask\app.py", line 1821, in handle_user_exception
    reraise(exc_type, exc_value, tb)
  File "C:\Users\accel\ProjectHome\phonogenesis\pyscript\venv\lib\site-packages\flask\_compat.py", line 39, in reraise
    raise value
  File "C:\Users\accel\ProjectHome\phonogenesis\pyscript\venv\lib\site-packages\flask\app.py", line 1950, in full_dispatch_request
    rv = self.dispatch_request()
  File "C:\Users\accel\ProjectHome\phonogenesis\pyscript\venv\lib\site-packages\flask\app.py", line 1936, in dispatch_request
    return self.view_functions[rule.endpoint](**req.view_args)
  File "C:\Users\accel\ProjectHome\phonogenesis\pyscript\app\routes.py", line 20, in environment_data
    return jsonify(DEFAULT_DATA)
  File "C:\Users\accel\ProjectHome\phonogenesis\pyscript\venv\lib\site-packages\flask\json\__init__.py", line 370, in jsonify
    dumps(data, indent=indent, separators=separators) + "\n",
  File "C:\Users\accel\ProjectHome\phonogenesis\pyscript\venv\lib\site-packages\flask\json\__init__.py", line 211, in dumps
    rv = _json.dumps(obj, **kwargs)
  File "C:\envbin\py37\lib\json\__init__.py", line 238, in dumps
    **kw).encode(obj)
  File "C:\envbin\py37\lib\json\encoder.py", line 199, in encode
    chunks = self.iterencode(o, _one_shot=True)
  File "C:\envbin\py37\lib\json\encoder.py", line 257, in iterencode
    return _iterencode(o, 0)
  File "C:\Users\accel\ProjectHome\phonogenesis\pyscript\venv\lib\site-packages\flask\json\__init__.py", line 100, in default
    return _json.JSONEncoder.default(self, o)
  File "C:\envbin\py37\lib\json\encoder.py", line 179, in default
    raise TypeError(f'Object of type {o.__class__.__name__} '
TypeError: Object of type Sound is not JSON serializable
[2020-06-15 12:24:11] - ERROR - Exception on /env [GET] - app 1892@log_exception
Traceback (most recent call last):
  File "C:\Users\accel\ProjectHome\phonogenesis\pyscript\venv\lib\site-packages\flask\app.py", line 2447, in wsgi_app
    response = self.full_dispatch_request()
  File "C:\Users\accel\ProjectHome\phonogenesis\pyscript\venv\lib\site-packages\flask\app.py", line 1952, in full_dispatch_request
    rv = self.handle_user_exception(e)
  File "C:\Users\accel\ProjectHome\phonogenesis\pyscript\venv\lib\site-packages\flask\app.py", line 1821, in handle_user_exception
    reraise(exc_type, exc_value, tb)
  File "C:\Users\accel\ProjectHome\phonogenesis\pyscript\venv\lib\site-packages\flask\_compat.py", line 39, in reraise
    raise value
  File "C:\Users\accel\ProjectHome\phonogenesis\pyscript\venv\lib\site-packages\flask\app.py", line 1950, in full_dispatch_request
    rv = self.dispatch_request()
  File "C:\Users\accel\ProjectHome\phonogenesis\pyscript\venv\lib\site-packages\flask\app.py", line 1936, in dispatch_request
    return self.view_functions[rule.endpoint](**req.view_args)
  File "C:\Users\accel\ProjectHome\phonogenesis\pyscript\app\routes.py", line 20, in environment_data
    return jsonify(DEFAULT_DATA)
  File "C:\Users\accel\ProjectHome\phonogenesis\pyscript\venv\lib\site-packages\flask\json\__init__.py", line 370, in jsonify
    dumps(data, indent=indent, separators=separators) + "\n",
  File "C:\Users\accel\ProjectHome\phonogenesis\pyscript\venv\lib\site-packages\flask\json\__init__.py", line 211, in dumps
    rv = _json.dumps(obj, **kwargs)
  File "C:\envbin\py37\lib\json\__init__.py", line 238, in dumps
    **kw).encode(obj)
  File "C:\envbin\py37\lib\json\encoder.py", line 199, in encode
    chunks = self.iterencode(o, _one_shot=True)
  File "C:\envbin\py37\lib\json\encoder.py", line 257, in iterencode
    return _iterencode(o, 0)
TypeError: '<' not supported between instances of 'Particle' and 'Particle'
[2020-06-15 12:25:47] - ERROR - Exception on /env [GET] - app 1892@log_exception
Traceback (most recent call last):
  File "C:\Users\accel\ProjectHome\phonogenesis\pyscript\venv\lib\site-packages\flask\app.py", line 2447, in wsgi_app
    response = self.full_dispatch_request()
  File "C:\Users\accel\ProjectHome\phonogenesis\pyscript\venv\lib\site-packages\flask\app.py", line 1952, in full_dispatch_request
    rv = self.handle_user_exception(e)
  File "C:\Users\accel\ProjectHome\phonogenesis\pyscript\venv\lib\site-packages\flask\app.py", line 1821, in handle_user_exception
    reraise(exc_type, exc_value, tb)
  File "C:\Users\accel\ProjectHome\phonogenesis\pyscript\venv\lib\site-packages\flask\_compat.py", line 39, in reraise
    raise value
  File "C:\Users\accel\ProjectHome\phonogenesis\pyscript\venv\lib\site-packages\flask\app.py", line 1950, in full_dispatch_request
    rv = self.dispatch_request()
  File "C:\Users\accel\ProjectHome\phonogenesis\pyscript\venv\lib\site-packages\flask\app.py", line 1936, in dispatch_request
    return self.view_functions[rule.endpoint](**req.view_args)
  File "C:\Users\accel\ProjectHome\phonogenesis\pyscript\app\routes.py", line 20, in environment_data
    return jsonify(DEFAULT_DATA)
  File "C:\Users\accel\ProjectHome\phonogenesis\pyscript\venv\lib\site-packages\flask\json\__init__.py", line 370, in jsonify
    dumps(data, indent=indent, separators=separators) + "\n",
  File "C:\Users\accel\ProjectHome\phonogenesis\pyscript\venv\lib\site-packages\flask\json\__init__.py", line 211, in dumps
    rv = _json.dumps(obj, **kwargs)
  File "C:\envbin\py37\lib\json\__init__.py", line 238, in dumps
    **kw).encode(obj)
  File "C:\envbin\py37\lib\json\encoder.py", line 199, in encode
    chunks = self.iterencode(o, _one_shot=True)
  File "C:\envbin\py37\lib\json\encoder.py", line 257, in iterencode
    return _iterencode(o, 0)
TypeError: '<' not supported between instances of 'Particle' and 'Particle'
[2020-06-15 12:26:21] - ERROR - Exception on /env [GET] - app 1892@log_exception
Traceback (most recent call last):
  File "C:\Users\accel\ProjectHome\phonogenesis\pyscript\venv\lib\site-packages\flask\app.py", line 2447, in wsgi_app
    response = self.full_dispatch_request()
  File "C:\Users\accel\ProjectHome\phonogenesis\pyscript\venv\lib\site-packages\flask\app.py", line 1952, in full_dispatch_request
    rv = self.handle_user_exception(e)
  File "C:\Users\accel\ProjectHome\phonogenesis\pyscript\venv\lib\site-packages\flask\app.py", line 1821, in handle_user_exception
    reraise(exc_type, exc_value, tb)
  File "C:\Users\accel\ProjectHome\phonogenesis\pyscript\venv\lib\site-packages\flask\_compat.py", line 39, in reraise
    raise value
  File "C:\Users\accel\ProjectHome\phonogenesis\pyscript\venv\lib\site-packages\flask\app.py", line 1950, in full_dispatch_request
    rv = self.dispatch_request()
  File "C:\Users\accel\ProjectHome\phonogenesis\pyscript\venv\lib\site-packages\flask\app.py", line 1936, in dispatch_request
    return self.view_functions[rule.endpoint](**req.view_args)
  File "C:\Users\accel\ProjectHome\phonogenesis\pyscript\app\routes.py", line 21, in environment_data
    return jsonify(DEFAULT_DATA)
  File "C:\Users\accel\ProjectHome\phonogenesis\pyscript\venv\lib\site-packages\flask\json\__init__.py", line 370, in jsonify
    dumps(data, indent=indent, separators=separators) + "\n",
  File "C:\Users\accel\ProjectHome\phonogenesis\pyscript\venv\lib\site-packages\flask\json\__init__.py", line 211, in dumps
    rv = _json.dumps(obj, **kwargs)
  File "C:\envbin\py37\lib\json\__init__.py", line 238, in dumps
    **kw).encode(obj)
  File "C:\envbin\py37\lib\json\encoder.py", line 199, in encode
    chunks = self.iterencode(o, _one_shot=True)
  File "C:\envbin\py37\lib\json\encoder.py", line 257, in iterencode
    return _iterencode(o, 0)
TypeError: '<' not supported between instances of 'Particle' and 'Particle'
[2020-06-15 12:32:04] - ERROR - Exception on /env [GET] - app 1892@log_exception
Traceback (most recent call last):
  File "C:\Users\accel\ProjectHome\phonogenesis\pyscript\venv\lib\site-packages\flask\app.py", line 2447, in wsgi_app
    response = self.full_dispatch_request()
  File "C:\Users\accel\ProjectHome\phonogenesis\pyscript\venv\lib\site-packages\flask\app.py", line 1952, in full_dispatch_request
    rv = self.handle_user_exception(e)
  File "C:\Users\accel\ProjectHome\phonogenesis\pyscript\venv\lib\site-packages\flask\app.py", line 1821, in handle_user_exception
    reraise(exc_type, exc_value, tb)
  File "C:\Users\accel\ProjectHome\phonogenesis\pyscript\venv\lib\site-packages\flask\_compat.py", line 39, in reraise
    raise value
  File "C:\Users\accel\ProjectHome\phonogenesis\pyscript\venv\lib\site-packages\flask\app.py", line 1950, in full_dispatch_request
    rv = self.dispatch_request()
  File "C:\Users\accel\ProjectHome\phonogenesis\pyscript\venv\lib\site-packages\flask\app.py", line 1936, in dispatch_request
    return self.view_functions[rule.endpoint](**req.view_args)
  File "C:\Users\accel\ProjectHome\phonogenesis\pyscript\app\routes.py", line 21, in environment_data
    return jsonify(DEFAULT_DATA['fs2s'])
  File "C:\Users\accel\ProjectHome\phonogenesis\pyscript\venv\lib\site-packages\flask\json\__init__.py", line 370, in jsonify
    dumps(data, indent=indent, separators=separators) + "\n",
  File "C:\Users\accel\ProjectHome\phonogenesis\pyscript\venv\lib\site-packages\flask\json\__init__.py", line 211, in dumps
    rv = _json.dumps(obj, **kwargs)
  File "C:\envbin\py37\lib\json\__init__.py", line 238, in dumps
    **kw).encode(obj)
  File "C:\envbin\py37\lib\json\encoder.py", line 199, in encode
    chunks = self.iterencode(o, _one_shot=True)
  File "C:\envbin\py37\lib\json\encoder.py", line 257, in iterencode
    return _iterencode(o, 0)
TypeError: '<' not supported between instances of 'Particle' and 'Particle'
[2020-06-15 12:37:02] - ERROR - Exception on /env [GET] - app 1892@log_exception
Traceback (most recent call last):
  File "C:\Users\accel\ProjectHome\phonogenesis\pyscript\venv\lib\site-packages\flask\app.py", line 2447, in wsgi_app
    response = self.full_dispatch_request()
  File "C:\Users\accel\ProjectHome\phonogenesis\pyscript\venv\lib\site-packages\flask\app.py", line 1952, in full_dispatch_request
    rv = self.handle_user_exception(e)
  File "C:\Users\accel\ProjectHome\phonogenesis\pyscript\venv\lib\site-packages\flask\app.py", line 1821, in handle_user_exception
    reraise(exc_type, exc_value, tb)
  File "C:\Users\accel\ProjectHome\phonogenesis\pyscript\venv\lib\site-packages\flask\_compat.py", line 39, in reraise
    raise value
  File "C:\Users\accel\ProjectHome\phonogenesis\pyscript\venv\lib\site-packages\flask\app.py", line 1950, in full_dispatch_request
    rv = self.dispatch_request()
  File "C:\Users\accel\ProjectHome\phonogenesis\pyscript\venv\lib\site-packages\flask\app.py", line 1936, in dispatch_request
    return self.view_functions[rule.endpoint](**req.view_args)
  File "C:\Users\accel\ProjectHome\phonogenesis\pyscript\app\routes.py", line 21, in environment_data
    return jsonify(DEFAULT_DATA)
  File "C:\Users\accel\ProjectHome\phonogenesis\pyscript\venv\lib\site-packages\flask\json\__init__.py", line 370, in jsonify
    dumps(data, indent=indent, separators=separators) + "\n",
  File "C:\Users\accel\ProjectHome\phonogenesis\pyscript\venv\lib\site-packages\flask\json\__init__.py", line 211, in dumps
    rv = _json.dumps(obj, **kwargs)
  File "C:\envbin\py37\lib\json\__init__.py", line 238, in dumps
    **kw).encode(obj)
  File "C:\envbin\py37\lib\json\encoder.py", line 199, in encode
    chunks = self.iterencode(o, _one_shot=True)
  File "C:\envbin\py37\lib\json\encoder.py", line 257, in iterencode
    return _iterencode(o, 0)
  File "C:\Users\accel\ProjectHome\phonogenesis\pyscript\app\__init__.py", line 23, in default
    return super(PhonogenesisJSONEncoder, self).default(o)
  File "C:\Users\accel\ProjectHome\phonogenesis\pyscript\venv\lib\site-packages\flask\json\__init__.py", line 100, in default
    return _json.JSONEncoder.default(self, o)
  File "C:\envbin\py37\lib\json\encoder.py", line 179, in default
    raise TypeError(f'Object of type {o.__class__.__name__} '
TypeError: Object of type GlossFamily is not JSON serializable
[2020-06-15 12:38:32] - ERROR - Exception on /env [GET] - app 1892@log_exception
Traceback (most recent call last):
  File "C:\Users\accel\ProjectHome\phonogenesis\pyscript\venv\lib\site-packages\flask\app.py", line 2447, in wsgi_app
    response = self.full_dispatch_request()
  File "C:\Users\accel\ProjectHome\phonogenesis\pyscript\venv\lib\site-packages\flask\app.py", line 1952, in full_dispatch_request
    rv = self.handle_user_exception(e)
  File "C:\Users\accel\ProjectHome\phonogenesis\pyscript\venv\lib\site-packages\flask\app.py", line 1821, in handle_user_exception
    reraise(exc_type, exc_value, tb)
  File "C:\Users\accel\ProjectHome\phonogenesis\pyscript\venv\lib\site-packages\flask\_compat.py", line 39, in reraise
    raise value
  File "C:\Users\accel\ProjectHome\phonogenesis\pyscript\venv\lib\site-packages\flask\app.py", line 1950, in full_dispatch_request
    rv = self.dispatch_request()
  File "C:\Users\accel\ProjectHome\phonogenesis\pyscript\venv\lib\site-packages\flask\app.py", line 1936, in dispatch_request
    return self.view_functions[rule.endpoint](**req.view_args)
  File "C:\Users\accel\ProjectHome\phonogenesis\pyscript\app\routes.py", line 21, in environment_data
    return jsonify(DEFAULT_DATA)
  File "C:\Users\accel\ProjectHome\phonogenesis\pyscript\venv\lib\site-packages\flask\json\__init__.py", line 370, in jsonify
    dumps(data, indent=indent, separators=separators) + "\n",
  File "C:\Users\accel\ProjectHome\phonogenesis\pyscript\venv\lib\site-packages\flask\json\__init__.py", line 211, in dumps
    rv = _json.dumps(obj, **kwargs)
  File "C:\envbin\py37\lib\json\__init__.py", line 238, in dumps
    **kw).encode(obj)
  File "C:\envbin\py37\lib\json\encoder.py", line 199, in encode
    chunks = self.iterencode(o, _one_shot=True)
  File "C:\envbin\py37\lib\json\encoder.py", line 257, in iterencode
    return _iterencode(o, 0)
  File "C:\Users\accel\ProjectHome\phonogenesis\pyscript\app\__init__.py", line 23, in default
    return super(PhonogenesisJSONEncoder, self).default(o)
  File "C:\Users\accel\ProjectHome\phonogenesis\pyscript\venv\lib\site-packages\flask\json\__init__.py", line 100, in default
    return _json.JSONEncoder.default(self, o)
  File "C:\envbin\py37\lib\json\encoder.py", line 179, in default
    raise TypeError(f'Object of type {o.__class__.__name__} '
TypeError: Object of type GlossFamily is not JSON serializable
[2020-06-15 12:39:10] - ERROR - Exception on /env [GET] - app 1892@log_exception
Traceback (most recent call last):
  File "C:\Users\accel\ProjectHome\phonogenesis\pyscript\venv\lib\site-packages\flask\app.py", line 2447, in wsgi_app
    response = self.full_dispatch_request()
  File "C:\Users\accel\ProjectHome\phonogenesis\pyscript\venv\lib\site-packages\flask\app.py", line 1952, in full_dispatch_request
    rv = self.handle_user_exception(e)
  File "C:\Users\accel\ProjectHome\phonogenesis\pyscript\venv\lib\site-packages\flask\app.py", line 1821, in handle_user_exception
    reraise(exc_type, exc_value, tb)
  File "C:\Users\accel\ProjectHome\phonogenesis\pyscript\venv\lib\site-packages\flask\_compat.py", line 39, in reraise
    raise value
  File "C:\Users\accel\ProjectHome\phonogenesis\pyscript\venv\lib\site-packages\flask\app.py", line 1950, in full_dispatch_request
    rv = self.dispatch_request()
  File "C:\Users\accel\ProjectHome\phonogenesis\pyscript\venv\lib\site-packages\flask\app.py", line 1936, in dispatch_request
    return self.view_functions[rule.endpoint](**req.view_args)
  File "C:\Users\accel\ProjectHome\phonogenesis\pyscript\app\routes.py", line 21, in environment_data
    return jsonify(DEFAULT_DATA)
  File "C:\Users\accel\ProjectHome\phonogenesis\pyscript\venv\lib\site-packages\flask\json\__init__.py", line 370, in jsonify
    dumps(data, indent=indent, separators=separators) + "\n",
  File "C:\Users\accel\ProjectHome\phonogenesis\pyscript\venv\lib\site-packages\flask\json\__init__.py", line 211, in dumps
    rv = _json.dumps(obj, **kwargs)
  File "C:\envbin\py37\lib\json\__init__.py", line 238, in dumps
    **kw).encode(obj)
  File "C:\envbin\py37\lib\json\encoder.py", line 199, in encode
    chunks = self.iterencode(o, _one_shot=True)
  File "C:\envbin\py37\lib\json\encoder.py", line 257, in iterencode
    return _iterencode(o, 0)
  File "C:\Users\accel\ProjectHome\phonogenesis\pyscript\app\__init__.py", line 23, in default
    return super(PhonogenesisJSONEncoder, self).default(o)
  File "C:\Users\accel\ProjectHome\phonogenesis\pyscript\venv\lib\site-packages\flask\json\__init__.py", line 100, in default
    return _json.JSONEncoder.default(self, o)
  File "C:\envbin\py37\lib\json\encoder.py", line 179, in default
    raise TypeError(f'Object of type {o.__class__.__name__} '
TypeError: Object of type RuleFamily is not JSON serializable
[2020-09-17 14:18:52] - ERROR - Exception on /env [GET] - app 1891@log_exception
Traceback (most recent call last):
  File "/home/snowsr/Projects/phonogenesis/pyscript/venv/lib/python3.8/site-packages/flask/app.py", line 2447, in wsgi_app
    response = self.full_dispatch_request()
  File "/home/snowsr/Projects/phonogenesis/pyscript/venv/lib/python3.8/site-packages/flask/app.py", line 1953, in full_dispatch_request
    return self.finalize_request(rv)
  File "/home/snowsr/Projects/phonogenesis/pyscript/venv/lib/python3.8/site-packages/flask/app.py", line 1970, in finalize_request
    response = self.process_response(response)
  File "/home/snowsr/Projects/phonogenesis/pyscript/venv/lib/python3.8/site-packages/flask/app.py", line 2267, in process_response
    response = handler(response)
  File "/home/snowsr/Projects/phonogenesis/pyscript/venv/lib/python3.8/site-packages/flask_cors/extension.py", line 185, in cors_after_request
    set_cors_headers(resp, res_options)
  File "/home/snowsr/Projects/phonogenesis/pyscript/venv/lib/python3.8/site-packages/flask_cors/core.py", line 245, in set_cors_headers
    headers_to_set = get_cors_headers(options, request.headers, request.method)
  File "/home/snowsr/Projects/phonogenesis/pyscript/venv/lib/python3.8/site-packages/flask_cors/core.py", line 177, in get_cors_headers
    origins_to_set = get_cors_origins(options, request_headers.get('Origin'))
  File "/home/snowsr/Projects/phonogenesis/pyscript/venv/lib/python3.8/site-packages/flask_cors/core.py", line 128, in get_cors_origins
    elif try_match_any(request_origin, origins):
  File "/home/snowsr/Projects/phonogenesis/pyscript/venv/lib/python3.8/site-packages/flask_cors/core.py", line 272, in try_match_any
    return any(try_match(inst, pattern) for pattern in patterns)
  File "/home/snowsr/Projects/phonogenesis/pyscript/venv/lib/python3.8/site-packages/flask_cors/core.py", line 272, in <genexpr>
    return any(try_match(inst, pattern) for pattern in patterns)
  File "/home/snowsr/Projects/phonogenesis/pyscript/venv/lib/python3.8/site-packages/flask_cors/core.py", line 279, in try_match
    elif probably_regex(maybe_regex):
  File "/home/snowsr/Projects/phonogenesis/pyscript/venv/lib/python3.8/site-packages/flask_cors/core.py", line 261, in probably_regex
    return any((c in maybe_regex for c in common_regex_chars))
  File "/home/snowsr/Projects/phonogenesis/pyscript/venv/lib/python3.8/site-packages/flask_cors/core.py", line 261, in <genexpr>
    return any((c in maybe_regex for c in common_regex_chars))
TypeError: argument of type 'bool' is not iterable
[2020-09-17 14:18:52] - ERROR - Request finalizing failed with an error while handling an error - app 1975@finalize_request
Traceback (most recent call last):
  File "/home/snowsr/Projects/phonogenesis/pyscript/venv/lib/python3.8/site-packages/flask/app.py", line 2447, in wsgi_app
    response = self.full_dispatch_request()
  File "/home/snowsr/Projects/phonogenesis/pyscript/venv/lib/python3.8/site-packages/flask/app.py", line 1953, in full_dispatch_request
    return self.finalize_request(rv)
  File "/home/snowsr/Projects/phonogenesis/pyscript/venv/lib/python3.8/site-packages/flask/app.py", line 1970, in finalize_request
    response = self.process_response(response)
  File "/home/snowsr/Projects/phonogenesis/pyscript/venv/lib/python3.8/site-packages/flask/app.py", line 2267, in process_response
    response = handler(response)
  File "/home/snowsr/Projects/phonogenesis/pyscript/venv/lib/python3.8/site-packages/flask_cors/extension.py", line 185, in cors_after_request
    set_cors_headers(resp, res_options)
  File "/home/snowsr/Projects/phonogenesis/pyscript/venv/lib/python3.8/site-packages/flask_cors/core.py", line 245, in set_cors_headers
    headers_to_set = get_cors_headers(options, request.headers, request.method)
  File "/home/snowsr/Projects/phonogenesis/pyscript/venv/lib/python3.8/site-packages/flask_cors/core.py", line 177, in get_cors_headers
    origins_to_set = get_cors_origins(options, request_headers.get('Origin'))
  File "/home/snowsr/Projects/phonogenesis/pyscript/venv/lib/python3.8/site-packages/flask_cors/core.py", line 128, in get_cors_origins
    elif try_match_any(request_origin, origins):
  File "/home/snowsr/Projects/phonogenesis/pyscript/venv/lib/python3.8/site-packages/flask_cors/core.py", line 272, in try_match_any
    return any(try_match(inst, pattern) for pattern in patterns)
  File "/home/snowsr/Projects/phonogenesis/pyscript/venv/lib/python3.8/site-packages/flask_cors/core.py", line 272, in <genexpr>
    return any(try_match(inst, pattern) for pattern in patterns)
  File "/home/snowsr/Projects/phonogenesis/pyscript/venv/lib/python3.8/site-packages/flask_cors/core.py", line 279, in try_match
    elif probably_regex(maybe_regex):
  File "/home/snowsr/Projects/phonogenesis/pyscript/venv/lib/python3.8/site-packages/flask_cors/core.py", line 261, in probably_regex
    return any((c in maybe_regex for c in common_regex_chars))
  File "/home/snowsr/Projects/phonogenesis/pyscript/venv/lib/python3.8/site-packages/flask_cors/core.py", line 261, in <genexpr>
    return any((c in maybe_regex for c in common_regex_chars))
TypeError: argument of type 'bool' is not iterable

During handling of the above exception, another exception occurred:

Traceback (most recent call last):
  File "/home/snowsr/Projects/phonogenesis/pyscript/venv/lib/python3.8/site-packages/flask/app.py", line 1970, in finalize_request
    response = self.process_response(response)
  File "/home/snowsr/Projects/phonogenesis/pyscript/venv/lib/python3.8/site-packages/flask/app.py", line 2267, in process_response
    response = handler(response)
  File "/home/snowsr/Projects/phonogenesis/pyscript/venv/lib/python3.8/site-packages/flask_cors/extension.py", line 185, in cors_after_request
    set_cors_headers(resp, res_options)
  File "/home/snowsr/Projects/phonogenesis/pyscript/venv/lib/python3.8/site-packages/flask_cors/core.py", line 245, in set_cors_headers
    headers_to_set = get_cors_headers(options, request.headers, request.method)
  File "/home/snowsr/Projects/phonogenesis/pyscript/venv/lib/python3.8/site-packages/flask_cors/core.py", line 177, in get_cors_headers
    origins_to_set = get_cors_origins(options, request_headers.get('Origin'))
  File "/home/snowsr/Projects/phonogenesis/pyscript/venv/lib/python3.8/site-packages/flask_cors/core.py", line 128, in get_cors_origins
    elif try_match_any(request_origin, origins):
  File "/home/snowsr/Projects/phonogenesis/pyscript/venv/lib/python3.8/site-packages/flask_cors/core.py", line 272, in try_match_any
    return any(try_match(inst, pattern) for pattern in patterns)
  File "/home/snowsr/Projects/phonogenesis/pyscript/venv/lib/python3.8/site-packages/flask_cors/core.py", line 272, in <genexpr>
    return any(try_match(inst, pattern) for pattern in patterns)
  File "/home/snowsr/Projects/phonogenesis/pyscript/venv/lib/python3.8/site-packages/flask_cors/core.py", line 279, in try_match
    elif probably_regex(maybe_regex):
  File "/home/snowsr/Projects/phonogenesis/pyscript/venv/lib/python3.8/site-packages/flask_cors/core.py", line 261, in probably_regex
    return any((c in maybe_regex for c in common_regex_chars))
  File "/home/snowsr/Projects/phonogenesis/pyscript/venv/lib/python3.8/site-packages/flask_cors/core.py", line 261, in <genexpr>
    return any((c in maybe_regex for c in common_regex_chars))
TypeError: argument of type 'bool' is not iterable
[2020-09-17 17:31:17] - ERROR - Exception on /users/check-session [GET] - app 1891@log_exception
Traceback (most recent call last):
  File "/home/snowsr/Projects/phonogenesis/pyscript/venv/lib/python3.8/site-packages/flask/app.py", line 2447, in wsgi_app
    response = self.full_dispatch_request()
  File "/home/snowsr/Projects/phonogenesis/pyscript/venv/lib/python3.8/site-packages/flask/app.py", line 1953, in full_dispatch_request
    return self.finalize_request(rv)
  File "/home/snowsr/Projects/phonogenesis/pyscript/venv/lib/python3.8/site-packages/flask/app.py", line 1968, in finalize_request
    response = self.make_response(rv)
  File "/home/snowsr/Projects/phonogenesis/pyscript/venv/lib/python3.8/site-packages/flask/app.py", line 2097, in make_response
    raise TypeError(
TypeError: The view function did not return a valid response. The function either returned None or ended without a return statement.
[2020-09-17 17:32:07] - ERROR - Exception on /users/check-session [GET] - app 1891@log_exception
Traceback (most recent call last):
  File "/home/snowsr/Projects/phonogenesis/pyscript/venv/lib/python3.8/site-packages/flask/app.py", line 2447, in wsgi_app
    response = self.full_dispatch_request()
  File "/home/snowsr/Projects/phonogenesis/pyscript/venv/lib/python3.8/site-packages/flask/app.py", line 1953, in full_dispatch_request
    return self.finalize_request(rv)
  File "/home/snowsr/Projects/phonogenesis/pyscript/venv/lib/python3.8/site-packages/flask/app.py", line 1968, in finalize_request
    response = self.make_response(rv)
  File "/home/snowsr/Projects/phonogenesis/pyscript/venv/lib/python3.8/site-packages/flask/app.py", line 2097, in make_response
    raise TypeError(
TypeError: The view function did not return a valid response. The function either returned None or ended without a return statement.
[2020-09-17 17:35:30] - ERROR - Exception on /users/login [POST] - app 1891@log_exception
Traceback (most recent call last):
  File "/home/snowsr/Projects/phonogenesis/pyscript/venv/lib/python3.8/site-packages/flask/app.py", line 2447, in wsgi_app
    response = self.full_dispatch_request()
  File "/home/snowsr/Projects/phonogenesis/pyscript/venv/lib/python3.8/site-packages/flask/app.py", line 1952, in full_dispatch_request
    rv = self.handle_user_exception(e)
  File "/home/snowsr/Projects/phonogenesis/pyscript/venv/lib/python3.8/site-packages/flask_cors/extension.py", line 165, in wrapped_function
    return cors_after_request(app.make_response(f(*args, **kwargs)))
  File "/home/snowsr/Projects/phonogenesis/pyscript/venv/lib/python3.8/site-packages/flask/app.py", line 1821, in handle_user_exception
    reraise(exc_type, exc_value, tb)
  File "/home/snowsr/Projects/phonogenesis/pyscript/venv/lib/python3.8/site-packages/flask/_compat.py", line 39, in reraise
    raise value
  File "/home/snowsr/Projects/phonogenesis/pyscript/venv/lib/python3.8/site-packages/flask/app.py", line 1950, in full_dispatch_request
    rv = self.dispatch_request()
  File "/home/snowsr/Projects/phonogenesis/pyscript/venv/lib/python3.8/site-packages/flask/app.py", line 1936, in dispatch_request
    return self.view_functions[rule.endpoint](**req.view_args)
  File "/home/snowsr/Projects/phonogenesis/pyscript/app/routes.py", line 21, in login
    print(request.headers['body'])
  File "/home/snowsr/Projects/phonogenesis/pyscript/venv/lib/python3.8/site-packages/werkzeug/datastructures.py", line 1463, in __getitem__
    return _unicodify_header_value(self.environ["HTTP_" + key])
KeyError: 'HTTP_BODY'
[2020-09-17 17:38:22] - ERROR - Exception on /users/login [POST] - app 1891@log_exception
Traceback (most recent call last):
  File "/home/snowsr/Projects/phonogenesis/pyscript/venv/lib/python3.8/site-packages/flask/app.py", line 2447, in wsgi_app
    response = self.full_dispatch_request()
  File "/home/snowsr/Projects/phonogenesis/pyscript/venv/lib/python3.8/site-packages/flask/app.py", line 1952, in full_dispatch_request
    rv = self.handle_user_exception(e)
  File "/home/snowsr/Projects/phonogenesis/pyscript/venv/lib/python3.8/site-packages/flask_cors/extension.py", line 165, in wrapped_function
    return cors_after_request(app.make_response(f(*args, **kwargs)))
  File "/home/snowsr/Projects/phonogenesis/pyscript/venv/lib/python3.8/site-packages/flask/app.py", line 1821, in handle_user_exception
    reraise(exc_type, exc_value, tb)
  File "/home/snowsr/Projects/phonogenesis/pyscript/venv/lib/python3.8/site-packages/flask/_compat.py", line 39, in reraise
    raise value
  File "/home/snowsr/Projects/phonogenesis/pyscript/venv/lib/python3.8/site-packages/flask/app.py", line 1950, in full_dispatch_request
    rv = self.dispatch_request()
  File "/home/snowsr/Projects/phonogenesis/pyscript/venv/lib/python3.8/site-packages/flask/app.py", line 1936, in dispatch_request
    return self.view_functions[rule.endpoint](**req.view_args)
  File "/home/snowsr/Projects/phonogenesis/pyscript/app/routes.py", line 21, in login
    print(request.data['username'])
TypeError: byte indices must be integers or slices, not str
[2020-09-17 17:43:24] - ERROR - Exception on /users/login [POST] - app 1891@log_exception
Traceback (most recent call last):
  File "/home/snowsr/Projects/phonogenesis/pyscript/venv/lib/python3.8/site-packages/flask/app.py", line 2447, in wsgi_app
    response = self.full_dispatch_request()
  File "/home/snowsr/Projects/phonogenesis/pyscript/venv/lib/python3.8/site-packages/flask/app.py", line 1952, in full_dispatch_request
    rv = self.handle_user_exception(e)
  File "/home/snowsr/Projects/phonogenesis/pyscript/venv/lib/python3.8/site-packages/flask_cors/extension.py", line 165, in wrapped_function
    return cors_after_request(app.make_response(f(*args, **kwargs)))
  File "/home/snowsr/Projects/phonogenesis/pyscript/venv/lib/python3.8/site-packages/flask/app.py", line 1821, in handle_user_exception
    reraise(exc_type, exc_value, tb)
  File "/home/snowsr/Projects/phonogenesis/pyscript/venv/lib/python3.8/site-packages/flask/_compat.py", line 39, in reraise
    raise value
  File "/home/snowsr/Projects/phonogenesis/pyscript/venv/lib/python3.8/site-packages/flask/app.py", line 1950, in full_dispatch_request
    rv = self.dispatch_request()
  File "/home/snowsr/Projects/phonogenesis/pyscript/venv/lib/python3.8/site-packages/flask/app.py", line 1936, in dispatch_request
    return self.view_functions[rule.endpoint](**req.view_args)
  File "/home/snowsr/Projects/phonogenesis/pyscript/app/routes.py", line 21, in login
    if current_user.is_autehnticated:
  File "/home/snowsr/Projects/phonogenesis/pyscript/venv/lib/python3.8/site-packages/werkzeug/local.py", line 347, in __getattr__
    return getattr(self._get_current_object(), name)
AttributeError: 'AnonymousUserMixin' object has no attribute 'is_autehnticated'
[2020-09-17 17:43:53] - ERROR - Exception on /users/check-session [GET] - app 1891@log_exception
Traceback (most recent call last):
  File "/home/snowsr/Projects/phonogenesis/pyscript/venv/lib/python3.8/site-packages/flask/app.py", line 2447, in wsgi_app
    response = self.full_dispatch_request()
  File "/home/snowsr/Projects/phonogenesis/pyscript/venv/lib/python3.8/site-packages/flask/app.py", line 1952, in full_dispatch_request
    rv = self.handle_user_exception(e)
  File "/home/snowsr/Projects/phonogenesis/pyscript/venv/lib/python3.8/site-packages/flask_cors/extension.py", line 165, in wrapped_function
    return cors_after_request(app.make_response(f(*args, **kwargs)))
  File "/home/snowsr/Projects/phonogenesis/pyscript/venv/lib/python3.8/site-packages/flask/app.py", line 1821, in handle_user_exception
    reraise(exc_type, exc_value, tb)
  File "/home/snowsr/Projects/phonogenesis/pyscript/venv/lib/python3.8/site-packages/flask/_compat.py", line 39, in reraise
    raise value
  File "/home/snowsr/Projects/phonogenesis/pyscript/venv/lib/python3.8/site-packages/flask/app.py", line 1950, in full_dispatch_request
    rv = self.dispatch_request()
  File "/home/snowsr/Projects/phonogenesis/pyscript/venv/lib/python3.8/site-packages/flask/app.py", line 1936, in dispatch_request
    return self.view_functions[rule.endpoint](**req.view_args)
  File "/home/snowsr/Projects/phonogenesis/pyscript/app/routes.py", line 35, in check_session
    return jsonify(currentUser=current_user)
  File "/home/snowsr/Projects/phonogenesis/pyscript/venv/lib/python3.8/site-packages/flask/json/__init__.py", line 370, in jsonify
    dumps(data, indent=indent, separators=separators) + "\n",
  File "/home/snowsr/Projects/phonogenesis/pyscript/venv/lib/python3.8/site-packages/flask/json/__init__.py", line 211, in dumps
    rv = _json.dumps(obj, **kwargs)
  File "/usr/lib/python3.8/json/__init__.py", line 234, in dumps
    return cls(
  File "/usr/lib/python3.8/json/encoder.py", line 199, in encode
    chunks = self.iterencode(o, _one_shot=True)
  File "/usr/lib/python3.8/json/encoder.py", line 257, in iterencode
    return _iterencode(o, 0)
  File "/home/snowsr/Projects/phonogenesis/pyscript/app/__init__.py", line 28, in default
    return super(PhonogenesisJSONEncoder, self).default(o)
  File "/home/snowsr/Projects/phonogenesis/pyscript/venv/lib/python3.8/site-packages/flask/json/__init__.py", line 100, in default
    return _json.JSONEncoder.default(self, o)
  File "/usr/lib/python3.8/json/encoder.py", line 179, in default
    raise TypeError(f'Object of type {o.__class__.__name__} '
TypeError: Object of type LocalProxy is not JSON serializable
[2020-09-17 17:44:28] - ERROR - Exception on /users/login [POST] - app 1891@log_exception
Traceback (most recent call last):
  File "/home/snowsr/Projects/phonogenesis/pyscript/venv/lib/python3.8/site-packages/flask/app.py", line 2447, in wsgi_app
    response = self.full_dispatch_request()
  File "/home/snowsr/Projects/phonogenesis/pyscript/venv/lib/python3.8/site-packages/flask/app.py", line 1952, in full_dispatch_request
    rv = self.handle_user_exception(e)
  File "/home/snowsr/Projects/phonogenesis/pyscript/venv/lib/python3.8/site-packages/flask_cors/extension.py", line 165, in wrapped_function
    return cors_after_request(app.make_response(f(*args, **kwargs)))
  File "/home/snowsr/Projects/phonogenesis/pyscript/venv/lib/python3.8/site-packages/flask/app.py", line 1821, in handle_user_exception
    reraise(exc_type, exc_value, tb)
  File "/home/snowsr/Projects/phonogenesis/pyscript/venv/lib/python3.8/site-packages/flask/_compat.py", line 39, in reraise
    raise value
  File "/home/snowsr/Projects/phonogenesis/pyscript/venv/lib/python3.8/site-packages/flask/app.py", line 1950, in full_dispatch_request
    rv = self.dispatch_request()
  File "/home/snowsr/Projects/phonogenesis/pyscript/venv/lib/python3.8/site-packages/flask/app.py", line 1936, in dispatch_request
    return self.view_functions[rule.endpoint](**req.view_args)
  File "/home/snowsr/Projects/phonogenesis/pyscript/app/routes.py", line 27, in login
    if user is None or not user.check_password(password):
  File "/home/snowsr/Projects/phonogenesis/pyscript/app/models.py", line 22, in check_password
    return check_password_hash(self.password_hash, password)
  File "/home/snowsr/Projects/phonogenesis/pyscript/venv/lib/python3.8/site-packages/werkzeug/security.py", line 218, in check_password_hash
    if pwhash.count("$") < 2:
AttributeError: 'NoneType' object has no attribute 'count'
[2020-09-17 19:01:52] - ERROR - Exception on /users/check-session [GET] - app 1891@log_exception
Traceback (most recent call last):
  File "/home/snowsr/Projects/phonogenesis/pyscript/venv/lib/python3.8/site-packages/flask/app.py", line 2447, in wsgi_app
    response = self.full_dispatch_request()
  File "/home/snowsr/Projects/phonogenesis/pyscript/venv/lib/python3.8/site-packages/flask/app.py", line 1952, in full_dispatch_request
    rv = self.handle_user_exception(e)
  File "/home/snowsr/Projects/phonogenesis/pyscript/venv/lib/python3.8/site-packages/flask_cors/extension.py", line 165, in wrapped_function
    return cors_after_request(app.make_response(f(*args, **kwargs)))
  File "/home/snowsr/Projects/phonogenesis/pyscript/venv/lib/python3.8/site-packages/flask/app.py", line 1821, in handle_user_exception
    reraise(exc_type, exc_value, tb)
  File "/home/snowsr/Projects/phonogenesis/pyscript/venv/lib/python3.8/site-packages/flask/_compat.py", line 39, in reraise
    raise value
  File "/home/snowsr/Projects/phonogenesis/pyscript/venv/lib/python3.8/site-packages/flask/app.py", line 1950, in full_dispatch_request
    rv = self.dispatch_request()
  File "/home/snowsr/Projects/phonogenesis/pyscript/venv/lib/python3.8/site-packages/flask/app.py", line 1936, in dispatch_request
    return self.view_functions[rule.endpoint](**req.view_args)
  File "/home/snowsr/Projects/phonogenesis/pyscript/app/routes.py", line 37, in check_session
    if session['user']:
  File "/home/snowsr/Projects/phonogenesis/pyscript/venv/lib/python3.8/site-packages/werkzeug/local.py", line 377, in <lambda>
    __getitem__ = lambda x, i: x._get_current_object()[i]
  File "/home/snowsr/Projects/phonogenesis/pyscript/venv/lib/python3.8/site-packages/flask/sessions.py", line 84, in __getitem__
    return super(SecureCookieSession, self).__getitem__(key)
KeyError: 'user'
[2020-09-17 19:02:50] - ERROR - Exception on /users/login [POST] - app 1891@log_exception
Traceback (most recent call last):
  File "/home/snowsr/Projects/phonogenesis/pyscript/venv/lib/python3.8/site-packages/flask/app.py", line 2447, in wsgi_app
    response = self.full_dispatch_request()
  File "/home/snowsr/Projects/phonogenesis/pyscript/venv/lib/python3.8/site-packages/flask/app.py", line 1952, in full_dispatch_request
    rv = self.handle_user_exception(e)
  File "/home/snowsr/Projects/phonogenesis/pyscript/venv/lib/python3.8/site-packages/flask_cors/extension.py", line 165, in wrapped_function
    return cors_after_request(app.make_response(f(*args, **kwargs)))
  File "/home/snowsr/Projects/phonogenesis/pyscript/venv/lib/python3.8/site-packages/flask/app.py", line 1821, in handle_user_exception
    reraise(exc_type, exc_value, tb)
  File "/home/snowsr/Projects/phonogenesis/pyscript/venv/lib/python3.8/site-packages/flask/_compat.py", line 39, in reraise
    raise value
  File "/home/snowsr/Projects/phonogenesis/pyscript/venv/lib/python3.8/site-packages/flask/app.py", line 1950, in full_dispatch_request
    rv = self.dispatch_request()
  File "/home/snowsr/Projects/phonogenesis/pyscript/venv/lib/python3.8/site-packages/flask/app.py", line 1936, in dispatch_request
    return self.view_functions[rule.endpoint](**req.view_args)
  File "/home/snowsr/Projects/phonogenesis/pyscript/app/routes.py", line 32, in login
    return jsonify(session['user'])
  File "/home/snowsr/Projects/phonogenesis/pyscript/venv/lib/python3.8/site-packages/flask/json/__init__.py", line 370, in jsonify
    dumps(data, indent=indent, separators=separators) + "\n",
  File "/home/snowsr/Projects/phonogenesis/pyscript/venv/lib/python3.8/site-packages/flask/json/__init__.py", line 211, in dumps
    rv = _json.dumps(obj, **kwargs)
  File "/usr/lib/python3.8/json/__init__.py", line 234, in dumps
    return cls(
  File "/usr/lib/python3.8/json/encoder.py", line 199, in encode
    chunks = self.iterencode(o, _one_shot=True)
  File "/usr/lib/python3.8/json/encoder.py", line 257, in iterencode
    return _iterencode(o, 0)
  File "/home/snowsr/Projects/phonogenesis/pyscript/app/__init__.py", line 28, in default
    return super(PhonogenesisJSONEncoder, self).default(o)
  File "/home/snowsr/Projects/phonogenesis/pyscript/venv/lib/python3.8/site-packages/flask/json/__init__.py", line 100, in default
    return _json.JSONEncoder.default(self, o)
  File "/usr/lib/python3.8/json/encoder.py", line 179, in default
    raise TypeError(f'Object of type {o.__class__.__name__} '
TypeError: Object of type User is not JSON serializable
[2020-09-17 19:02:50] - ERROR - Request finalizing failed with an error while handling an error - app 1975@finalize_request
Traceback (most recent call last):
  File "/home/snowsr/Projects/phonogenesis/pyscript/venv/lib/python3.8/site-packages/flask/app.py", line 2447, in wsgi_app
    response = self.full_dispatch_request()
  File "/home/snowsr/Projects/phonogenesis/pyscript/venv/lib/python3.8/site-packages/flask/app.py", line 1952, in full_dispatch_request
    rv = self.handle_user_exception(e)
  File "/home/snowsr/Projects/phonogenesis/pyscript/venv/lib/python3.8/site-packages/flask_cors/extension.py", line 165, in wrapped_function
    return cors_after_request(app.make_response(f(*args, **kwargs)))
  File "/home/snowsr/Projects/phonogenesis/pyscript/venv/lib/python3.8/site-packages/flask/app.py", line 1821, in handle_user_exception
    reraise(exc_type, exc_value, tb)
  File "/home/snowsr/Projects/phonogenesis/pyscript/venv/lib/python3.8/site-packages/flask/_compat.py", line 39, in reraise
    raise value
  File "/home/snowsr/Projects/phonogenesis/pyscript/venv/lib/python3.8/site-packages/flask/app.py", line 1950, in full_dispatch_request
    rv = self.dispatch_request()
  File "/home/snowsr/Projects/phonogenesis/pyscript/venv/lib/python3.8/site-packages/flask/app.py", line 1936, in dispatch_request
    return self.view_functions[rule.endpoint](**req.view_args)
  File "/home/snowsr/Projects/phonogenesis/pyscript/app/routes.py", line 32, in login
    return jsonify(session['user'])
  File "/home/snowsr/Projects/phonogenesis/pyscript/venv/lib/python3.8/site-packages/flask/json/__init__.py", line 370, in jsonify
    dumps(data, indent=indent, separators=separators) + "\n",
  File "/home/snowsr/Projects/phonogenesis/pyscript/venv/lib/python3.8/site-packages/flask/json/__init__.py", line 211, in dumps
    rv = _json.dumps(obj, **kwargs)
  File "/usr/lib/python3.8/json/__init__.py", line 234, in dumps
    return cls(
  File "/usr/lib/python3.8/json/encoder.py", line 199, in encode
    chunks = self.iterencode(o, _one_shot=True)
  File "/usr/lib/python3.8/json/encoder.py", line 257, in iterencode
    return _iterencode(o, 0)
  File "/home/snowsr/Projects/phonogenesis/pyscript/app/__init__.py", line 28, in default
    return super(PhonogenesisJSONEncoder, self).default(o)
  File "/home/snowsr/Projects/phonogenesis/pyscript/venv/lib/python3.8/site-packages/flask/json/__init__.py", line 100, in default
    return _json.JSONEncoder.default(self, o)
  File "/usr/lib/python3.8/json/encoder.py", line 179, in default
    raise TypeError(f'Object of type {o.__class__.__name__} '
TypeError: Object of type User is not JSON serializable

During handling of the above exception, another exception occurred:

Traceback (most recent call last):
  File "/home/snowsr/Projects/phonogenesis/pyscript/venv/lib/python3.8/site-packages/flask/app.py", line 1970, in finalize_request
    response = self.process_response(response)
  File "/home/snowsr/Projects/phonogenesis/pyscript/venv/lib/python3.8/site-packages/flask/app.py", line 2269, in process_response
    self.session_interface.save_session(self, ctx.session, response)
  File "/home/snowsr/Projects/phonogenesis/pyscript/venv/lib/python3.8/site-packages/flask/sessions.py", line 378, in save_session
    val = self.get_signing_serializer(app).dumps(dict(session))
  File "/home/snowsr/Projects/phonogenesis/pyscript/venv/lib/python3.8/site-packages/itsdangerous/serializer.py", line 166, in dumps
    payload = want_bytes(self.dump_payload(obj))
  File "/home/snowsr/Projects/phonogenesis/pyscript/venv/lib/python3.8/site-packages/itsdangerous/url_safe.py", line 42, in dump_payload
    json = super(URLSafeSerializerMixin, self).dump_payload(obj)
  File "/home/snowsr/Projects/phonogenesis/pyscript/venv/lib/python3.8/site-packages/itsdangerous/serializer.py", line 133, in dump_payload
    return want_bytes(self.serializer.dumps(obj, **self.serializer_kwargs))
  File "/home/snowsr/Projects/phonogenesis/pyscript/venv/lib/python3.8/site-packages/flask/json/tag.py", line 305, in dumps
    return dumps(self.tag(value), separators=(",", ":"))
  File "/home/snowsr/Projects/phonogenesis/pyscript/venv/lib/python3.8/site-packages/flask/json/__init__.py", line 211, in dumps
    rv = _json.dumps(obj, **kwargs)
  File "/usr/lib/python3.8/json/__init__.py", line 234, in dumps
    return cls(
  File "/usr/lib/python3.8/json/encoder.py", line 199, in encode
    chunks = self.iterencode(o, _one_shot=True)
  File "/usr/lib/python3.8/json/encoder.py", line 257, in iterencode
    return _iterencode(o, 0)
  File "/home/snowsr/Projects/phonogenesis/pyscript/app/__init__.py", line 28, in default
    return super(PhonogenesisJSONEncoder, self).default(o)
  File "/home/snowsr/Projects/phonogenesis/pyscript/venv/lib/python3.8/site-packages/flask/json/__init__.py", line 100, in default
    return _json.JSONEncoder.default(self, o)
  File "/usr/lib/python3.8/json/encoder.py", line 179, in default
    raise TypeError(f'Object of type {o.__class__.__name__} '
TypeError: Object of type User is not JSON serializable
[2020-09-17 19:08:22] - ERROR - Exception on /users/login [POST] - app 1891@log_exception
Traceback (most recent call last):
  File "/home/snowsr/Projects/phonogenesis/pyscript/venv/lib/python3.8/site-packages/flask/app.py", line 2447, in wsgi_app
    response = self.full_dispatch_request()
  File "/home/snowsr/Projects/phonogenesis/pyscript/venv/lib/python3.8/site-packages/flask/app.py", line 1952, in full_dispatch_request
    rv = self.handle_user_exception(e)
  File "/home/snowsr/Projects/phonogenesis/pyscript/venv/lib/python3.8/site-packages/flask_cors/extension.py", line 165, in wrapped_function
    return cors_after_request(app.make_response(f(*args, **kwargs)))
  File "/home/snowsr/Projects/phonogenesis/pyscript/venv/lib/python3.8/site-packages/flask/app.py", line 1821, in handle_user_exception
    reraise(exc_type, exc_value, tb)
  File "/home/snowsr/Projects/phonogenesis/pyscript/venv/lib/python3.8/site-packages/flask/_compat.py", line 39, in reraise
    raise value
  File "/home/snowsr/Projects/phonogenesis/pyscript/venv/lib/python3.8/site-packages/flask/app.py", line 1950, in full_dispatch_request
    rv = self.dispatch_request()
  File "/home/snowsr/Projects/phonogenesis/pyscript/venv/lib/python3.8/site-packages/flask/app.py", line 1936, in dispatch_request
    return self.view_functions[rule.endpoint](**req.view_args)
  File "/home/snowsr/Projects/phonogenesis/pyscript/app/routes.py", line 32, in login
    return jsonify(session['user'])
  File "/home/snowsr/Projects/phonogenesis/pyscript/venv/lib/python3.8/site-packages/flask/json/__init__.py", line 370, in jsonify
    dumps(data, indent=indent, separators=separators) + "\n",
  File "/home/snowsr/Projects/phonogenesis/pyscript/venv/lib/python3.8/site-packages/flask/json/__init__.py", line 211, in dumps
    rv = _json.dumps(obj, **kwargs)
  File "/usr/lib/python3.8/json/__init__.py", line 234, in dumps
    return cls(
  File "/usr/lib/python3.8/json/encoder.py", line 199, in encode
    chunks = self.iterencode(o, _one_shot=True)
  File "/usr/lib/python3.8/json/encoder.py", line 257, in iterencode
    return _iterencode(o, 0)
  File "/home/snowsr/Projects/phonogenesis/pyscript/app/__init__.py", line 29, in default
    return super(PhonogenesisJSONEncoder, self).default(o)
  File "/home/snowsr/Projects/phonogenesis/pyscript/venv/lib/python3.8/site-packages/flask/json/__init__.py", line 100, in default
    return _json.JSONEncoder.default(self, o)
  File "/usr/lib/python3.8/json/encoder.py", line 179, in default
    raise TypeError(f'Object of type {o.__class__.__name__} '
TypeError: Object of type AppenderBaseQuery is not JSON serializable
[2020-09-17 19:08:22] - ERROR - Request finalizing failed with an error while handling an error - app 1975@finalize_request
Traceback (most recent call last):
  File "/home/snowsr/Projects/phonogenesis/pyscript/venv/lib/python3.8/site-packages/flask/app.py", line 2447, in wsgi_app
    response = self.full_dispatch_request()
  File "/home/snowsr/Projects/phonogenesis/pyscript/venv/lib/python3.8/site-packages/flask/app.py", line 1952, in full_dispatch_request
    rv = self.handle_user_exception(e)
  File "/home/snowsr/Projects/phonogenesis/pyscript/venv/lib/python3.8/site-packages/flask_cors/extension.py", line 165, in wrapped_function
    return cors_after_request(app.make_response(f(*args, **kwargs)))
  File "/home/snowsr/Projects/phonogenesis/pyscript/venv/lib/python3.8/site-packages/flask/app.py", line 1821, in handle_user_exception
    reraise(exc_type, exc_value, tb)
  File "/home/snowsr/Projects/phonogenesis/pyscript/venv/lib/python3.8/site-packages/flask/_compat.py", line 39, in reraise
    raise value
  File "/home/snowsr/Projects/phonogenesis/pyscript/venv/lib/python3.8/site-packages/flask/app.py", line 1950, in full_dispatch_request
    rv = self.dispatch_request()
  File "/home/snowsr/Projects/phonogenesis/pyscript/venv/lib/python3.8/site-packages/flask/app.py", line 1936, in dispatch_request
    return self.view_functions[rule.endpoint](**req.view_args)
  File "/home/snowsr/Projects/phonogenesis/pyscript/app/routes.py", line 32, in login
    return jsonify(session['user'])
  File "/home/snowsr/Projects/phonogenesis/pyscript/venv/lib/python3.8/site-packages/flask/json/__init__.py", line 370, in jsonify
    dumps(data, indent=indent, separators=separators) + "\n",
  File "/home/snowsr/Projects/phonogenesis/pyscript/venv/lib/python3.8/site-packages/flask/json/__init__.py", line 211, in dumps
    rv = _json.dumps(obj, **kwargs)
  File "/usr/lib/python3.8/json/__init__.py", line 234, in dumps
    return cls(
  File "/usr/lib/python3.8/json/encoder.py", line 199, in encode
    chunks = self.iterencode(o, _one_shot=True)
  File "/usr/lib/python3.8/json/encoder.py", line 257, in iterencode
    return _iterencode(o, 0)
  File "/home/snowsr/Projects/phonogenesis/pyscript/app/__init__.py", line 29, in default
    return super(PhonogenesisJSONEncoder, self).default(o)
  File "/home/snowsr/Projects/phonogenesis/pyscript/venv/lib/python3.8/site-packages/flask/json/__init__.py", line 100, in default
    return _json.JSONEncoder.default(self, o)
  File "/usr/lib/python3.8/json/encoder.py", line 179, in default
    raise TypeError(f'Object of type {o.__class__.__name__} '
TypeError: Object of type AppenderBaseQuery is not JSON serializable

During handling of the above exception, another exception occurred:

Traceback (most recent call last):
  File "/home/snowsr/Projects/phonogenesis/pyscript/venv/lib/python3.8/site-packages/flask/app.py", line 1970, in finalize_request
    response = self.process_response(response)
  File "/home/snowsr/Projects/phonogenesis/pyscript/venv/lib/python3.8/site-packages/flask/app.py", line 2269, in process_response
    self.session_interface.save_session(self, ctx.session, response)
  File "/home/snowsr/Projects/phonogenesis/pyscript/venv/lib/python3.8/site-packages/flask/sessions.py", line 378, in save_session
    val = self.get_signing_serializer(app).dumps(dict(session))
  File "/home/snowsr/Projects/phonogenesis/pyscript/venv/lib/python3.8/site-packages/itsdangerous/serializer.py", line 166, in dumps
    payload = want_bytes(self.dump_payload(obj))
  File "/home/snowsr/Projects/phonogenesis/pyscript/venv/lib/python3.8/site-packages/itsdangerous/url_safe.py", line 42, in dump_payload
    json = super(URLSafeSerializerMixin, self).dump_payload(obj)
  File "/home/snowsr/Projects/phonogenesis/pyscript/venv/lib/python3.8/site-packages/itsdangerous/serializer.py", line 133, in dump_payload
    return want_bytes(self.serializer.dumps(obj, **self.serializer_kwargs))
  File "/home/snowsr/Projects/phonogenesis/pyscript/venv/lib/python3.8/site-packages/flask/json/tag.py", line 305, in dumps
    return dumps(self.tag(value), separators=(",", ":"))
  File "/home/snowsr/Projects/phonogenesis/pyscript/venv/lib/python3.8/site-packages/flask/json/__init__.py", line 211, in dumps
    rv = _json.dumps(obj, **kwargs)
  File "/usr/lib/python3.8/json/__init__.py", line 234, in dumps
    return cls(
  File "/usr/lib/python3.8/json/encoder.py", line 199, in encode
    chunks = self.iterencode(o, _one_shot=True)
  File "/usr/lib/python3.8/json/encoder.py", line 257, in iterencode
    return _iterencode(o, 0)
  File "/home/snowsr/Projects/phonogenesis/pyscript/app/__init__.py", line 29, in default
    return super(PhonogenesisJSONEncoder, self).default(o)
  File "/home/snowsr/Projects/phonogenesis/pyscript/venv/lib/python3.8/site-packages/flask/json/__init__.py", line 100, in default
    return _json.JSONEncoder.default(self, o)
  File "/usr/lib/python3.8/json/encoder.py", line 179, in default
    raise TypeError(f'Object of type {o.__class__.__name__} '
TypeError: Object of type AppenderBaseQuery is not JSON serializable
[2020-09-17 19:09:29] - ERROR - Exception on /users/check-session [GET] - app 1891@log_exception
Traceback (most recent call last):
  File "/home/snowsr/Projects/phonogenesis/pyscript/venv/lib/python3.8/site-packages/flask/app.py", line 2447, in wsgi_app
    response = self.full_dispatch_request()
  File "/home/snowsr/Projects/phonogenesis/pyscript/venv/lib/python3.8/site-packages/flask/app.py", line 1952, in full_dispatch_request
    rv = self.handle_user_exception(e)
  File "/home/snowsr/Projects/phonogenesis/pyscript/venv/lib/python3.8/site-packages/flask_cors/extension.py", line 165, in wrapped_function
    return cors_after_request(app.make_response(f(*args, **kwargs)))
  File "/home/snowsr/Projects/phonogenesis/pyscript/venv/lib/python3.8/site-packages/flask/app.py", line 1821, in handle_user_exception
    reraise(exc_type, exc_value, tb)
  File "/home/snowsr/Projects/phonogenesis/pyscript/venv/lib/python3.8/site-packages/flask/_compat.py", line 39, in reraise
    raise value
  File "/home/snowsr/Projects/phonogenesis/pyscript/venv/lib/python3.8/site-packages/flask/app.py", line 1950, in full_dispatch_request
    rv = self.dispatch_request()
  File "/home/snowsr/Projects/phonogenesis/pyscript/venv/lib/python3.8/site-packages/flask/app.py", line 1936, in dispatch_request
    return self.view_functions[rule.endpoint](**req.view_args)
  File "/home/snowsr/Projects/phonogenesis/pyscript/app/routes.py", line 38, in check_session
    return jsonify(currentUser=jsonify(session['user']))
  File "/home/snowsr/Projects/phonogenesis/pyscript/venv/lib/python3.8/site-packages/flask/json/__init__.py", line 370, in jsonify
    dumps(data, indent=indent, separators=separators) + "\n",
  File "/home/snowsr/Projects/phonogenesis/pyscript/venv/lib/python3.8/site-packages/flask/json/__init__.py", line 211, in dumps
    rv = _json.dumps(obj, **kwargs)
  File "/usr/lib/python3.8/json/__init__.py", line 234, in dumps
    return cls(
  File "/usr/lib/python3.8/json/encoder.py", line 199, in encode
    chunks = self.iterencode(o, _one_shot=True)
  File "/usr/lib/python3.8/json/encoder.py", line 257, in iterencode
    return _iterencode(o, 0)
  File "/home/snowsr/Projects/phonogenesis/pyscript/app/__init__.py", line 29, in default
    return super(PhonogenesisJSONEncoder, self).default(o)
  File "/home/snowsr/Projects/phonogenesis/pyscript/venv/lib/python3.8/site-packages/flask/json/__init__.py", line 100, in default
    return _json.JSONEncoder.default(self, o)
  File "/usr/lib/python3.8/json/encoder.py", line 179, in default
    raise TypeError(f'Object of type {o.__class__.__name__} '
TypeError: Object of type Response is not JSON serializable
[2020-09-17 19:09:43] - ERROR - Exception on /users/check-session [GET] - app 1891@log_exception
Traceback (most recent call last):
  File "/home/snowsr/Projects/phonogenesis/pyscript/venv/lib/python3.8/site-packages/flask/app.py", line 2447, in wsgi_app
    response = self.full_dispatch_request()
  File "/home/snowsr/Projects/phonogenesis/pyscript/venv/lib/python3.8/site-packages/flask/app.py", line 1952, in full_dispatch_request
    rv = self.handle_user_exception(e)
  File "/home/snowsr/Projects/phonogenesis/pyscript/venv/lib/python3.8/site-packages/flask_cors/extension.py", line 165, in wrapped_function
    return cors_after_request(app.make_response(f(*args, **kwargs)))
  File "/home/snowsr/Projects/phonogenesis/pyscript/venv/lib/python3.8/site-packages/flask/app.py", line 1821, in handle_user_exception
    reraise(exc_type, exc_value, tb)
  File "/home/snowsr/Projects/phonogenesis/pyscript/venv/lib/python3.8/site-packages/flask/_compat.py", line 39, in reraise
    raise value
  File "/home/snowsr/Projects/phonogenesis/pyscript/venv/lib/python3.8/site-packages/flask/app.py", line 1950, in full_dispatch_request
    rv = self.dispatch_request()
  File "/home/snowsr/Projects/phonogenesis/pyscript/venv/lib/python3.8/site-packages/flask/app.py", line 1936, in dispatch_request
    return self.view_functions[rule.endpoint](**req.view_args)
  File "/home/snowsr/Projects/phonogenesis/pyscript/app/routes.py", line 38, in check_session
    return jsonify(currentUser=jsonify(session['user']))
  File "/home/snowsr/Projects/phonogenesis/pyscript/venv/lib/python3.8/site-packages/flask/json/__init__.py", line 370, in jsonify
    dumps(data, indent=indent, separators=separators) + "\n",
  File "/home/snowsr/Projects/phonogenesis/pyscript/venv/lib/python3.8/site-packages/flask/json/__init__.py", line 211, in dumps
    rv = _json.dumps(obj, **kwargs)
  File "/usr/lib/python3.8/json/__init__.py", line 234, in dumps
    return cls(
  File "/usr/lib/python3.8/json/encoder.py", line 199, in encode
    chunks = self.iterencode(o, _one_shot=True)
  File "/usr/lib/python3.8/json/encoder.py", line 257, in iterencode
    return _iterencode(o, 0)
  File "/home/snowsr/Projects/phonogenesis/pyscript/app/__init__.py", line 29, in default
    return super(PhonogenesisJSONEncoder, self).default(o)
  File "/home/snowsr/Projects/phonogenesis/pyscript/venv/lib/python3.8/site-packages/flask/json/__init__.py", line 100, in default
    return _json.JSONEncoder.default(self, o)
  File "/usr/lib/python3.8/json/encoder.py", line 179, in default
    raise TypeError(f'Object of type {o.__class__.__name__} '
TypeError: Object of type Response is not JSON serializable
[2020-09-17 19:10:35] - ERROR - Exception on /users/check-session [GET] - app 1891@log_exception
Traceback (most recent call last):
  File "/home/snowsr/Projects/phonogenesis/pyscript/venv/lib/python3.8/site-packages/flask/app.py", line 2447, in wsgi_app
    response = self.full_dispatch_request()
  File "/home/snowsr/Projects/phonogenesis/pyscript/venv/lib/python3.8/site-packages/flask/app.py", line 1952, in full_dispatch_request
    rv = self.handle_user_exception(e)
  File "/home/snowsr/Projects/phonogenesis/pyscript/venv/lib/python3.8/site-packages/flask_cors/extension.py", line 165, in wrapped_function
    return cors_after_request(app.make_response(f(*args, **kwargs)))
  File "/home/snowsr/Projects/phonogenesis/pyscript/venv/lib/python3.8/site-packages/flask/app.py", line 1821, in handle_user_exception
    reraise(exc_type, exc_value, tb)
  File "/home/snowsr/Projects/phonogenesis/pyscript/venv/lib/python3.8/site-packages/flask/_compat.py", line 39, in reraise
    raise value
  File "/home/snowsr/Projects/phonogenesis/pyscript/venv/lib/python3.8/site-packages/flask/app.py", line 1950, in full_dispatch_request
    rv = self.dispatch_request()
  File "/home/snowsr/Projects/phonogenesis/pyscript/venv/lib/python3.8/site-packages/flask/app.py", line 1936, in dispatch_request
    return self.view_functions[rule.endpoint](**req.view_args)
  File "/home/snowsr/Projects/phonogenesis/pyscript/app/routes.py", line 38, in check_session
    return jsonify(currentUser=jsonify(session['user']))
  File "/home/snowsr/Projects/phonogenesis/pyscript/venv/lib/python3.8/site-packages/flask/json/__init__.py", line 370, in jsonify
    dumps(data, indent=indent, separators=separators) + "\n",
  File "/home/snowsr/Projects/phonogenesis/pyscript/venv/lib/python3.8/site-packages/flask/json/__init__.py", line 211, in dumps
    rv = _json.dumps(obj, **kwargs)
  File "/usr/lib/python3.8/json/__init__.py", line 234, in dumps
    return cls(
  File "/usr/lib/python3.8/json/encoder.py", line 199, in encode
    chunks = self.iterencode(o, _one_shot=True)
  File "/usr/lib/python3.8/json/encoder.py", line 257, in iterencode
    return _iterencode(o, 0)
  File "/home/snowsr/Projects/phonogenesis/pyscript/app/__init__.py", line 29, in default
    return super(PhonogenesisJSONEncoder, self).default(o)
  File "/home/snowsr/Projects/phonogenesis/pyscript/venv/lib/python3.8/site-packages/flask/json/__init__.py", line 100, in default
    return _json.JSONEncoder.default(self, o)
  File "/usr/lib/python3.8/json/encoder.py", line 179, in default
    raise TypeError(f'Object of type {o.__class__.__name__} '
TypeError: Object of type Response is not JSON serializable
[2020-09-17 19:12:02] - ERROR - Exception on /users/check-session [GET] - app 1891@log_exception
Traceback (most recent call last):
  File "/home/snowsr/Projects/phonogenesis/pyscript/venv/lib/python3.8/site-packages/flask/app.py", line 2447, in wsgi_app
    response = self.full_dispatch_request()
  File "/home/snowsr/Projects/phonogenesis/pyscript/venv/lib/python3.8/site-packages/flask/app.py", line 1952, in full_dispatch_request
    rv = self.handle_user_exception(e)
  File "/home/snowsr/Projects/phonogenesis/pyscript/venv/lib/python3.8/site-packages/flask_cors/extension.py", line 165, in wrapped_function
    return cors_after_request(app.make_response(f(*args, **kwargs)))
  File "/home/snowsr/Projects/phonogenesis/pyscript/venv/lib/python3.8/site-packages/flask/app.py", line 1821, in handle_user_exception
    reraise(exc_type, exc_value, tb)
  File "/home/snowsr/Projects/phonogenesis/pyscript/venv/lib/python3.8/site-packages/flask/_compat.py", line 39, in reraise
    raise value
  File "/home/snowsr/Projects/phonogenesis/pyscript/venv/lib/python3.8/site-packages/flask/app.py", line 1950, in full_dispatch_request
    rv = self.dispatch_request()
  File "/home/snowsr/Projects/phonogenesis/pyscript/venv/lib/python3.8/site-packages/flask/app.py", line 1936, in dispatch_request
    return self.view_functions[rule.endpoint](**req.view_args)
  File "/home/snowsr/Projects/phonogenesis/pyscript/app/routes.py", line 39, in check_session
    return jsonify(currentUser=jsonify(session['user']))
  File "/home/snowsr/Projects/phonogenesis/pyscript/venv/lib/python3.8/site-packages/flask/json/__init__.py", line 370, in jsonify
    dumps(data, indent=indent, separators=separators) + "\n",
  File "/home/snowsr/Projects/phonogenesis/pyscript/venv/lib/python3.8/site-packages/flask/json/__init__.py", line 211, in dumps
    rv = _json.dumps(obj, **kwargs)
  File "/usr/lib/python3.8/json/__init__.py", line 234, in dumps
    return cls(
  File "/usr/lib/python3.8/json/encoder.py", line 199, in encode
    chunks = self.iterencode(o, _one_shot=True)
  File "/usr/lib/python3.8/json/encoder.py", line 257, in iterencode
    return _iterencode(o, 0)
  File "/home/snowsr/Projects/phonogenesis/pyscript/app/__init__.py", line 29, in default
    return super(PhonogenesisJSONEncoder, self).default(o)
  File "/home/snowsr/Projects/phonogenesis/pyscript/venv/lib/python3.8/site-packages/flask/json/__init__.py", line 100, in default
    return _json.JSONEncoder.default(self, o)
  File "/usr/lib/python3.8/json/encoder.py", line 179, in default
    raise TypeError(f'Object of type {o.__class__.__name__} '
TypeError: Object of type Response is not JSON serializable
[2020-09-17 19:13:29] - ERROR - Exception on /users/check-session [GET] - app 1891@log_exception
Traceback (most recent call last):
  File "/home/snowsr/Projects/phonogenesis/pyscript/venv/lib/python3.8/site-packages/flask/app.py", line 2447, in wsgi_app
    response = self.full_dispatch_request()
  File "/home/snowsr/Projects/phonogenesis/pyscript/venv/lib/python3.8/site-packages/flask/app.py", line 1952, in full_dispatch_request
    rv = self.handle_user_exception(e)
  File "/home/snowsr/Projects/phonogenesis/pyscript/venv/lib/python3.8/site-packages/flask_cors/extension.py", line 165, in wrapped_function
    return cors_after_request(app.make_response(f(*args, **kwargs)))
  File "/home/snowsr/Projects/phonogenesis/pyscript/venv/lib/python3.8/site-packages/flask/app.py", line 1821, in handle_user_exception
    reraise(exc_type, exc_value, tb)
  File "/home/snowsr/Projects/phonogenesis/pyscript/venv/lib/python3.8/site-packages/flask/_compat.py", line 39, in reraise
    raise value
  File "/home/snowsr/Projects/phonogenesis/pyscript/venv/lib/python3.8/site-packages/flask/app.py", line 1950, in full_dispatch_request
    rv = self.dispatch_request()
  File "/home/snowsr/Projects/phonogenesis/pyscript/venv/lib/python3.8/site-packages/flask/app.py", line 1936, in dispatch_request
    return self.view_functions[rule.endpoint](**req.view_args)
  File "/home/snowsr/Projects/phonogenesis/pyscript/app/routes.py", line 39, in check_session
    return make_response(jsonify(currentUser=jsonify(session['user'])))
  File "/home/snowsr/Projects/phonogenesis/pyscript/venv/lib/python3.8/site-packages/flask/json/__init__.py", line 370, in jsonify
    dumps(data, indent=indent, separators=separators) + "\n",
  File "/home/snowsr/Projects/phonogenesis/pyscript/venv/lib/python3.8/site-packages/flask/json/__init__.py", line 211, in dumps
    rv = _json.dumps(obj, **kwargs)
  File "/usr/lib/python3.8/json/__init__.py", line 234, in dumps
    return cls(
  File "/usr/lib/python3.8/json/encoder.py", line 199, in encode
    chunks = self.iterencode(o, _one_shot=True)
  File "/usr/lib/python3.8/json/encoder.py", line 257, in iterencode
    return _iterencode(o, 0)
  File "/home/snowsr/Projects/phonogenesis/pyscript/app/__init__.py", line 29, in default
    return super(PhonogenesisJSONEncoder, self).default(o)
  File "/home/snowsr/Projects/phonogenesis/pyscript/venv/lib/python3.8/site-packages/flask/json/__init__.py", line 100, in default
    return _json.JSONEncoder.default(self, o)
  File "/usr/lib/python3.8/json/encoder.py", line 179, in default
    raise TypeError(f'Object of type {o.__class__.__name__} '
TypeError: Object of type Response is not JSON serializable
[2020-09-17 19:13:46] - ERROR - Exception on /users/check-session [GET] - app 1891@log_exception
Traceback (most recent call last):
  File "/home/snowsr/Projects/phonogenesis/pyscript/venv/lib/python3.8/site-packages/flask/app.py", line 2447, in wsgi_app
    response = self.full_dispatch_request()
  File "/home/snowsr/Projects/phonogenesis/pyscript/venv/lib/python3.8/site-packages/flask/app.py", line 1952, in full_dispatch_request
    rv = self.handle_user_exception(e)
  File "/home/snowsr/Projects/phonogenesis/pyscript/venv/lib/python3.8/site-packages/flask_cors/extension.py", line 165, in wrapped_function
    return cors_after_request(app.make_response(f(*args, **kwargs)))
  File "/home/snowsr/Projects/phonogenesis/pyscript/venv/lib/python3.8/site-packages/flask/app.py", line 1821, in handle_user_exception
    reraise(exc_type, exc_value, tb)
  File "/home/snowsr/Projects/phonogenesis/pyscript/venv/lib/python3.8/site-packages/flask/_compat.py", line 39, in reraise
    raise value
  File "/home/snowsr/Projects/phonogenesis/pyscript/venv/lib/python3.8/site-packages/flask/app.py", line 1950, in full_dispatch_request
    rv = self.dispatch_request()
  File "/home/snowsr/Projects/phonogenesis/pyscript/venv/lib/python3.8/site-packages/flask/app.py", line 1936, in dispatch_request
    return self.view_functions[rule.endpoint](**req.view_args)
  File "/home/snowsr/Projects/phonogenesis/pyscript/app/routes.py", line 39, in check_session
    return make_response(jsonify(currentUser=jsonify(session['user'])))
  File "/home/snowsr/Projects/phonogenesis/pyscript/venv/lib/python3.8/site-packages/flask/json/__init__.py", line 370, in jsonify
    dumps(data, indent=indent, separators=separators) + "\n",
  File "/home/snowsr/Projects/phonogenesis/pyscript/venv/lib/python3.8/site-packages/flask/json/__init__.py", line 211, in dumps
    rv = _json.dumps(obj, **kwargs)
  File "/usr/lib/python3.8/json/__init__.py", line 234, in dumps
    return cls(
  File "/usr/lib/python3.8/json/encoder.py", line 199, in encode
    chunks = self.iterencode(o, _one_shot=True)
  File "/usr/lib/python3.8/json/encoder.py", line 257, in iterencode
    return _iterencode(o, 0)
  File "/home/snowsr/Projects/phonogenesis/pyscript/app/__init__.py", line 29, in default
    return super(PhonogenesisJSONEncoder, self).default(o)
  File "/home/snowsr/Projects/phonogenesis/pyscript/venv/lib/python3.8/site-packages/flask/json/__init__.py", line 100, in default
    return _json.JSONEncoder.default(self, o)
  File "/usr/lib/python3.8/json/encoder.py", line 179, in default
    raise TypeError(f'Object of type {o.__class__.__name__} '
TypeError: Object of type Response is not JSON serializable
[2020-09-17 19:14:47] - ERROR - Exception on /users/check-session [GET] - app 1891@log_exception
Traceback (most recent call last):
  File "/home/snowsr/Projects/phonogenesis/pyscript/venv/lib/python3.8/site-packages/flask/app.py", line 2447, in wsgi_app
    response = self.full_dispatch_request()
  File "/home/snowsr/Projects/phonogenesis/pyscript/venv/lib/python3.8/site-packages/flask/app.py", line 1952, in full_dispatch_request
    rv = self.handle_user_exception(e)
  File "/home/snowsr/Projects/phonogenesis/pyscript/venv/lib/python3.8/site-packages/flask_cors/extension.py", line 165, in wrapped_function
    return cors_after_request(app.make_response(f(*args, **kwargs)))
  File "/home/snowsr/Projects/phonogenesis/pyscript/venv/lib/python3.8/site-packages/flask/app.py", line 1821, in handle_user_exception
    reraise(exc_type, exc_value, tb)
  File "/home/snowsr/Projects/phonogenesis/pyscript/venv/lib/python3.8/site-packages/flask/_compat.py", line 39, in reraise
    raise value
  File "/home/snowsr/Projects/phonogenesis/pyscript/venv/lib/python3.8/site-packages/flask/app.py", line 1950, in full_dispatch_request
    rv = self.dispatch_request()
  File "/home/snowsr/Projects/phonogenesis/pyscript/venv/lib/python3.8/site-packages/flask/app.py", line 1936, in dispatch_request
    return self.view_functions[rule.endpoint](**req.view_args)
  File "/home/snowsr/Projects/phonogenesis/pyscript/app/routes.py", line 39, in check_session
    return make_response(jsonify(currentUser=jsonify(session['user'])))
  File "/home/snowsr/Projects/phonogenesis/pyscript/venv/lib/python3.8/site-packages/flask/json/__init__.py", line 370, in jsonify
    dumps(data, indent=indent, separators=separators) + "\n",
  File "/home/snowsr/Projects/phonogenesis/pyscript/venv/lib/python3.8/site-packages/flask/json/__init__.py", line 211, in dumps
    rv = _json.dumps(obj, **kwargs)
  File "/usr/lib/python3.8/json/__init__.py", line 234, in dumps
    return cls(
  File "/usr/lib/python3.8/json/encoder.py", line 199, in encode
    chunks = self.iterencode(o, _one_shot=True)
  File "/usr/lib/python3.8/json/encoder.py", line 257, in iterencode
    return _iterencode(o, 0)
  File "/home/snowsr/Projects/phonogenesis/pyscript/app/__init__.py", line 29, in default
    return super(PhonogenesisJSONEncoder, self).default(o)
  File "/home/snowsr/Projects/phonogenesis/pyscript/venv/lib/python3.8/site-packages/flask/json/__init__.py", line 100, in default
    return _json.JSONEncoder.default(self, o)
  File "/usr/lib/python3.8/json/encoder.py", line 179, in default
    raise TypeError(f'Object of type {o.__class__.__name__} '
TypeError: Object of type Response is not JSON serializable
[2020-09-17 19:16:28] - ERROR - Exception on /users/check-session [GET] - app 1891@log_exception
Traceback (most recent call last):
  File "/home/snowsr/Projects/phonogenesis/pyscript/app/__init__.py", line 30, in default
    return o.serialize()
AttributeError: 'Response' object has no attribute 'serialize'

During handling of the above exception, another exception occurred:

Traceback (most recent call last):
  File "/home/snowsr/Projects/phonogenesis/pyscript/venv/lib/python3.8/site-packages/flask/app.py", line 2447, in wsgi_app
    response = self.full_dispatch_request()
  File "/home/snowsr/Projects/phonogenesis/pyscript/venv/lib/python3.8/site-packages/flask/app.py", line 1952, in full_dispatch_request
    rv = self.handle_user_exception(e)
  File "/home/snowsr/Projects/phonogenesis/pyscript/venv/lib/python3.8/site-packages/flask_cors/extension.py", line 165, in wrapped_function
    return cors_after_request(app.make_response(f(*args, **kwargs)))
  File "/home/snowsr/Projects/phonogenesis/pyscript/venv/lib/python3.8/site-packages/flask/app.py", line 1821, in handle_user_exception
    reraise(exc_type, exc_value, tb)
  File "/home/snowsr/Projects/phonogenesis/pyscript/venv/lib/python3.8/site-packages/flask/_compat.py", line 39, in reraise
    raise value
  File "/home/snowsr/Projects/phonogenesis/pyscript/venv/lib/python3.8/site-packages/flask/app.py", line 1950, in full_dispatch_request
    rv = self.dispatch_request()
  File "/home/snowsr/Projects/phonogenesis/pyscript/venv/lib/python3.8/site-packages/flask/app.py", line 1936, in dispatch_request
    return self.view_functions[rule.endpoint](**req.view_args)
  File "/home/snowsr/Projects/phonogenesis/pyscript/app/routes.py", line 39, in check_session
    return make_response(jsonify(currentUser=jsonify(session['user'])))
  File "/home/snowsr/Projects/phonogenesis/pyscript/venv/lib/python3.8/site-packages/flask/json/__init__.py", line 370, in jsonify
    dumps(data, indent=indent, separators=separators) + "\n",
  File "/home/snowsr/Projects/phonogenesis/pyscript/venv/lib/python3.8/site-packages/flask/json/__init__.py", line 211, in dumps
    rv = _json.dumps(obj, **kwargs)
  File "/usr/lib/python3.8/json/__init__.py", line 234, in dumps
    return cls(
  File "/usr/lib/python3.8/json/encoder.py", line 199, in encode
    chunks = self.iterencode(o, _one_shot=True)
  File "/usr/lib/python3.8/json/encoder.py", line 257, in iterencode
    return _iterencode(o, 0)
  File "/home/snowsr/Projects/phonogenesis/pyscript/app/__init__.py", line 32, in default
    return super(PhonogenesisJSONEncoder, self).default(o)
  File "/home/snowsr/Projects/phonogenesis/pyscript/venv/lib/python3.8/site-packages/flask/json/__init__.py", line 100, in default
    return _json.JSONEncoder.default(self, o)
  File "/usr/lib/python3.8/json/encoder.py", line 179, in default
    raise TypeError(f'Object of type {o.__class__.__name__} '
TypeError: Object of type Response is not JSON serializable
[2020-09-17 22:14:04] - ERROR - Exception on /user/login [POST] - app 1891@log_exception
Traceback (most recent call last):
  File "/home/snowsr/Projects/phonogenesis/pyscript/venv/lib/python3.8/site-packages/sqlalchemy/engine/base.py", line 1276, in _execute_context
    self.dialect.do_execute(
  File "/home/snowsr/Projects/phonogenesis/pyscript/venv/lib/python3.8/site-packages/sqlalchemy/engine/default.py", line 593, in do_execute
    cursor.execute(statement, parameters)
sqlite3.OperationalError: no such table: usergroup

The above exception was the direct cause of the following exception:

Traceback (most recent call last):
  File "/home/snowsr/Projects/phonogenesis/pyscript/venv/lib/python3.8/site-packages/flask/app.py", line 2447, in wsgi_app
    response = self.full_dispatch_request()
  File "/home/snowsr/Projects/phonogenesis/pyscript/venv/lib/python3.8/site-packages/flask/app.py", line 1952, in full_dispatch_request
    rv = self.handle_user_exception(e)
  File "/home/snowsr/Projects/phonogenesis/pyscript/venv/lib/python3.8/site-packages/flask_cors/extension.py", line 165, in wrapped_function
    return cors_after_request(app.make_response(f(*args, **kwargs)))
  File "/home/snowsr/Projects/phonogenesis/pyscript/venv/lib/python3.8/site-packages/flask/app.py", line 1821, in handle_user_exception
    reraise(exc_type, exc_value, tb)
  File "/home/snowsr/Projects/phonogenesis/pyscript/venv/lib/python3.8/site-packages/flask/_compat.py", line 39, in reraise
    raise value
  File "/home/snowsr/Projects/phonogenesis/pyscript/venv/lib/python3.8/site-packages/flask/app.py", line 1950, in full_dispatch_request
    rv = self.dispatch_request()
  File "/home/snowsr/Projects/phonogenesis/pyscript/venv/lib/python3.8/site-packages/flask/app.py", line 1936, in dispatch_request
    return self.view_functions[rule.endpoint](**req.view_args)
  File "/home/snowsr/Projects/phonogenesis/pyscript/app/routes.py", line 37, in login
    return jsonify(result=session['user'])
  File "/home/snowsr/Projects/phonogenesis/pyscript/venv/lib/python3.8/site-packages/flask/json/__init__.py", line 370, in jsonify
    dumps(data, indent=indent, separators=separators) + "\n",
  File "/home/snowsr/Projects/phonogenesis/pyscript/venv/lib/python3.8/site-packages/flask/json/__init__.py", line 211, in dumps
    rv = _json.dumps(obj, **kwargs)
  File "/usr/lib/python3.8/json/__init__.py", line 234, in dumps
    return cls(
  File "/usr/lib/python3.8/json/encoder.py", line 199, in encode
    chunks = self.iterencode(o, _one_shot=True)
  File "/usr/lib/python3.8/json/encoder.py", line 257, in iterencode
    return _iterencode(o, 0)
  File "/home/snowsr/Projects/phonogenesis/pyscript/app/__init__.py", line 28, in default
    return o.serialize()
  File "/home/snowsr/Projects/phonogenesis/pyscript/app/models.py", line 74, in serialize
    groups = UserGroup.query.filter_by(user_id=self.id).all()
  File "/home/snowsr/Projects/phonogenesis/pyscript/venv/lib/python3.8/site-packages/sqlalchemy/orm/query.py", line 3346, in all
    return list(self)
  File "/home/snowsr/Projects/phonogenesis/pyscript/venv/lib/python3.8/site-packages/sqlalchemy/orm/query.py", line 3508, in __iter__
    return self._execute_and_instances(context)
  File "/home/snowsr/Projects/phonogenesis/pyscript/venv/lib/python3.8/site-packages/sqlalchemy/orm/query.py", line 3533, in _execute_and_instances
    result = conn.execute(querycontext.statement, self._params)
  File "/home/snowsr/Projects/phonogenesis/pyscript/venv/lib/python3.8/site-packages/sqlalchemy/engine/base.py", line 1011, in execute
    return meth(self, multiparams, params)
  File "/home/snowsr/Projects/phonogenesis/pyscript/venv/lib/python3.8/site-packages/sqlalchemy/sql/elements.py", line 298, in _execute_on_connection
    return connection._execute_clauseelement(self, multiparams, params)
  File "/home/snowsr/Projects/phonogenesis/pyscript/venv/lib/python3.8/site-packages/sqlalchemy/engine/base.py", line 1124, in _execute_clauseelement
    ret = self._execute_context(
  File "/home/snowsr/Projects/phonogenesis/pyscript/venv/lib/python3.8/site-packages/sqlalchemy/engine/base.py", line 1316, in _execute_context
    self._handle_dbapi_exception(
  File "/home/snowsr/Projects/phonogenesis/pyscript/venv/lib/python3.8/site-packages/sqlalchemy/engine/base.py", line 1510, in _handle_dbapi_exception
    util.raise_(
  File "/home/snowsr/Projects/phonogenesis/pyscript/venv/lib/python3.8/site-packages/sqlalchemy/util/compat.py", line 182, in raise_
    raise exception
  File "/home/snowsr/Projects/phonogenesis/pyscript/venv/lib/python3.8/site-packages/sqlalchemy/engine/base.py", line 1276, in _execute_context
    self.dialect.do_execute(
  File "/home/snowsr/Projects/phonogenesis/pyscript/venv/lib/python3.8/site-packages/sqlalchemy/engine/default.py", line 593, in do_execute
    cursor.execute(statement, parameters)
sqlalchemy.exc.OperationalError: (sqlite3.OperationalError) no such table: usergroup
[SQL: SELECT usergroup.id AS usergroup_id, usergroup.group_id AS usergroup_group_id, usergroup.user_id AS usergroup_user_id 
FROM usergroup 
WHERE usergroup.user_id = ?]
[parameters: (1,)]
(Background on this error at: http://sqlalche.me/e/13/e3q8)
[2020-09-17 22:14:04] - ERROR - Request finalizing failed with an error while handling an error - app 1975@finalize_request
Traceback (most recent call last):
  File "/home/snowsr/Projects/phonogenesis/pyscript/venv/lib/python3.8/site-packages/sqlalchemy/engine/base.py", line 1276, in _execute_context
    self.dialect.do_execute(
  File "/home/snowsr/Projects/phonogenesis/pyscript/venv/lib/python3.8/site-packages/sqlalchemy/engine/default.py", line 593, in do_execute
    cursor.execute(statement, parameters)
sqlite3.OperationalError: no such table: usergroup

The above exception was the direct cause of the following exception:

Traceback (most recent call last):
  File "/home/snowsr/Projects/phonogenesis/pyscript/venv/lib/python3.8/site-packages/flask/app.py", line 2447, in wsgi_app
    response = self.full_dispatch_request()
  File "/home/snowsr/Projects/phonogenesis/pyscript/venv/lib/python3.8/site-packages/flask/app.py", line 1952, in full_dispatch_request
    rv = self.handle_user_exception(e)
  File "/home/snowsr/Projects/phonogenesis/pyscript/venv/lib/python3.8/site-packages/flask_cors/extension.py", line 165, in wrapped_function
    return cors_after_request(app.make_response(f(*args, **kwargs)))
  File "/home/snowsr/Projects/phonogenesis/pyscript/venv/lib/python3.8/site-packages/flask/app.py", line 1821, in handle_user_exception
    reraise(exc_type, exc_value, tb)
  File "/home/snowsr/Projects/phonogenesis/pyscript/venv/lib/python3.8/site-packages/flask/_compat.py", line 39, in reraise
    raise value
  File "/home/snowsr/Projects/phonogenesis/pyscript/venv/lib/python3.8/site-packages/flask/app.py", line 1950, in full_dispatch_request
    rv = self.dispatch_request()
  File "/home/snowsr/Projects/phonogenesis/pyscript/venv/lib/python3.8/site-packages/flask/app.py", line 1936, in dispatch_request
    return self.view_functions[rule.endpoint](**req.view_args)
  File "/home/snowsr/Projects/phonogenesis/pyscript/app/routes.py", line 37, in login
    return jsonify(result=session['user'])
  File "/home/snowsr/Projects/phonogenesis/pyscript/venv/lib/python3.8/site-packages/flask/json/__init__.py", line 370, in jsonify
    dumps(data, indent=indent, separators=separators) + "\n",
  File "/home/snowsr/Projects/phonogenesis/pyscript/venv/lib/python3.8/site-packages/flask/json/__init__.py", line 211, in dumps
    rv = _json.dumps(obj, **kwargs)
  File "/usr/lib/python3.8/json/__init__.py", line 234, in dumps
    return cls(
  File "/usr/lib/python3.8/json/encoder.py", line 199, in encode
    chunks = self.iterencode(o, _one_shot=True)
  File "/usr/lib/python3.8/json/encoder.py", line 257, in iterencode
    return _iterencode(o, 0)
  File "/home/snowsr/Projects/phonogenesis/pyscript/app/__init__.py", line 28, in default
    return o.serialize()
  File "/home/snowsr/Projects/phonogenesis/pyscript/app/models.py", line 74, in serialize
    groups = UserGroup.query.filter_by(user_id=self.id).all()
  File "/home/snowsr/Projects/phonogenesis/pyscript/venv/lib/python3.8/site-packages/sqlalchemy/orm/query.py", line 3346, in all
    return list(self)
  File "/home/snowsr/Projects/phonogenesis/pyscript/venv/lib/python3.8/site-packages/sqlalchemy/orm/query.py", line 3508, in __iter__
    return self._execute_and_instances(context)
  File "/home/snowsr/Projects/phonogenesis/pyscript/venv/lib/python3.8/site-packages/sqlalchemy/orm/query.py", line 3533, in _execute_and_instances
    result = conn.execute(querycontext.statement, self._params)
  File "/home/snowsr/Projects/phonogenesis/pyscript/venv/lib/python3.8/site-packages/sqlalchemy/engine/base.py", line 1011, in execute
    return meth(self, multiparams, params)
  File "/home/snowsr/Projects/phonogenesis/pyscript/venv/lib/python3.8/site-packages/sqlalchemy/sql/elements.py", line 298, in _execute_on_connection
    return connection._execute_clauseelement(self, multiparams, params)
  File "/home/snowsr/Projects/phonogenesis/pyscript/venv/lib/python3.8/site-packages/sqlalchemy/engine/base.py", line 1124, in _execute_clauseelement
    ret = self._execute_context(
  File "/home/snowsr/Projects/phonogenesis/pyscript/venv/lib/python3.8/site-packages/sqlalchemy/engine/base.py", line 1316, in _execute_context
    self._handle_dbapi_exception(
  File "/home/snowsr/Projects/phonogenesis/pyscript/venv/lib/python3.8/site-packages/sqlalchemy/engine/base.py", line 1510, in _handle_dbapi_exception
    util.raise_(
  File "/home/snowsr/Projects/phonogenesis/pyscript/venv/lib/python3.8/site-packages/sqlalchemy/util/compat.py", line 182, in raise_
    raise exception
  File "/home/snowsr/Projects/phonogenesis/pyscript/venv/lib/python3.8/site-packages/sqlalchemy/engine/base.py", line 1276, in _execute_context
    self.dialect.do_execute(
  File "/home/snowsr/Projects/phonogenesis/pyscript/venv/lib/python3.8/site-packages/sqlalchemy/engine/default.py", line 593, in do_execute
    cursor.execute(statement, parameters)
sqlalchemy.exc.OperationalError: (sqlite3.OperationalError) no such table: usergroup
[SQL: SELECT usergroup.id AS usergroup_id, usergroup.group_id AS usergroup_group_id, usergroup.user_id AS usergroup_user_id 
FROM usergroup 
WHERE usergroup.user_id = ?]
[parameters: (1,)]
(Background on this error at: http://sqlalche.me/e/13/e3q8)

During handling of the above exception, another exception occurred:

Traceback (most recent call last):
  File "/home/snowsr/Projects/phonogenesis/pyscript/venv/lib/python3.8/site-packages/sqlalchemy/engine/base.py", line 1276, in _execute_context
    self.dialect.do_execute(
  File "/home/snowsr/Projects/phonogenesis/pyscript/venv/lib/python3.8/site-packages/sqlalchemy/engine/default.py", line 593, in do_execute
    cursor.execute(statement, parameters)
sqlite3.OperationalError: no such table: usergroup

The above exception was the direct cause of the following exception:

Traceback (most recent call last):
  File "/home/snowsr/Projects/phonogenesis/pyscript/venv/lib/python3.8/site-packages/flask/app.py", line 1970, in finalize_request
    response = self.process_response(response)
  File "/home/snowsr/Projects/phonogenesis/pyscript/venv/lib/python3.8/site-packages/flask/app.py", line 2269, in process_response
    self.session_interface.save_session(self, ctx.session, response)
  File "/home/snowsr/Projects/phonogenesis/pyscript/venv/lib/python3.8/site-packages/flask/sessions.py", line 378, in save_session
    val = self.get_signing_serializer(app).dumps(dict(session))
  File "/home/snowsr/Projects/phonogenesis/pyscript/venv/lib/python3.8/site-packages/itsdangerous/serializer.py", line 166, in dumps
    payload = want_bytes(self.dump_payload(obj))
  File "/home/snowsr/Projects/phonogenesis/pyscript/venv/lib/python3.8/site-packages/itsdangerous/url_safe.py", line 42, in dump_payload
    json = super(URLSafeSerializerMixin, self).dump_payload(obj)
  File "/home/snowsr/Projects/phonogenesis/pyscript/venv/lib/python3.8/site-packages/itsdangerous/serializer.py", line 133, in dump_payload
    return want_bytes(self.serializer.dumps(obj, **self.serializer_kwargs))
  File "/home/snowsr/Projects/phonogenesis/pyscript/venv/lib/python3.8/site-packages/flask/json/tag.py", line 305, in dumps
    return dumps(self.tag(value), separators=(",", ":"))
  File "/home/snowsr/Projects/phonogenesis/pyscript/venv/lib/python3.8/site-packages/flask/json/__init__.py", line 211, in dumps
    rv = _json.dumps(obj, **kwargs)
  File "/usr/lib/python3.8/json/__init__.py", line 234, in dumps
    return cls(
  File "/usr/lib/python3.8/json/encoder.py", line 199, in encode
    chunks = self.iterencode(o, _one_shot=True)
  File "/usr/lib/python3.8/json/encoder.py", line 257, in iterencode
    return _iterencode(o, 0)
  File "/home/snowsr/Projects/phonogenesis/pyscript/app/__init__.py", line 28, in default
    return o.serialize()
  File "/home/snowsr/Projects/phonogenesis/pyscript/app/models.py", line 74, in serialize
    groups = UserGroup.query.filter_by(user_id=self.id).all()
  File "/home/snowsr/Projects/phonogenesis/pyscript/venv/lib/python3.8/site-packages/sqlalchemy/orm/query.py", line 3346, in all
    return list(self)
  File "/home/snowsr/Projects/phonogenesis/pyscript/venv/lib/python3.8/site-packages/sqlalchemy/orm/query.py", line 3508, in __iter__
    return self._execute_and_instances(context)
  File "/home/snowsr/Projects/phonogenesis/pyscript/venv/lib/python3.8/site-packages/sqlalchemy/orm/query.py", line 3533, in _execute_and_instances
    result = conn.execute(querycontext.statement, self._params)
  File "/home/snowsr/Projects/phonogenesis/pyscript/venv/lib/python3.8/site-packages/sqlalchemy/engine/base.py", line 1011, in execute
    return meth(self, multiparams, params)
  File "/home/snowsr/Projects/phonogenesis/pyscript/venv/lib/python3.8/site-packages/sqlalchemy/sql/elements.py", line 298, in _execute_on_connection
    return connection._execute_clauseelement(self, multiparams, params)
  File "/home/snowsr/Projects/phonogenesis/pyscript/venv/lib/python3.8/site-packages/sqlalchemy/engine/base.py", line 1124, in _execute_clauseelement
    ret = self._execute_context(
  File "/home/snowsr/Projects/phonogenesis/pyscript/venv/lib/python3.8/site-packages/sqlalchemy/engine/base.py", line 1316, in _execute_context
    self._handle_dbapi_exception(
  File "/home/snowsr/Projects/phonogenesis/pyscript/venv/lib/python3.8/site-packages/sqlalchemy/engine/base.py", line 1510, in _handle_dbapi_exception
    util.raise_(
  File "/home/snowsr/Projects/phonogenesis/pyscript/venv/lib/python3.8/site-packages/sqlalchemy/util/compat.py", line 182, in raise_
    raise exception
  File "/home/snowsr/Projects/phonogenesis/pyscript/venv/lib/python3.8/site-packages/sqlalchemy/engine/base.py", line 1276, in _execute_context
    self.dialect.do_execute(
  File "/home/snowsr/Projects/phonogenesis/pyscript/venv/lib/python3.8/site-packages/sqlalchemy/engine/default.py", line 593, in do_execute
    cursor.execute(statement, parameters)
sqlalchemy.exc.OperationalError: (sqlite3.OperationalError) no such table: usergroup
[SQL: SELECT usergroup.id AS usergroup_id, usergroup.group_id AS usergroup_group_id, usergroup.user_id AS usergroup_user_id 
FROM usergroup 
WHERE usergroup.user_id = ?]
[parameters: (1,)]
(Background on this error at: http://sqlalche.me/e/13/e3q8)
[2020-09-17 22:54:15] - ERROR - Exception on /user/login [POST] - app 1891@log_exception
Traceback (most recent call last):
  File "/home/snowsr/Projects/phonogenesis/pyscript/venv/lib/python3.8/site-packages/flask/app.py", line 2447, in wsgi_app
    response = self.full_dispatch_request()
  File "/home/snowsr/Projects/phonogenesis/pyscript/venv/lib/python3.8/site-packages/flask/app.py", line 1952, in full_dispatch_request
    rv = self.handle_user_exception(e)
  File "/home/snowsr/Projects/phonogenesis/pyscript/venv/lib/python3.8/site-packages/flask_cors/extension.py", line 165, in wrapped_function
    return cors_after_request(app.make_response(f(*args, **kwargs)))
  File "/home/snowsr/Projects/phonogenesis/pyscript/venv/lib/python3.8/site-packages/flask/app.py", line 1821, in handle_user_exception
    reraise(exc_type, exc_value, tb)
  File "/home/snowsr/Projects/phonogenesis/pyscript/venv/lib/python3.8/site-packages/flask/_compat.py", line 39, in reraise
    raise value
  File "/home/snowsr/Projects/phonogenesis/pyscript/venv/lib/python3.8/site-packages/flask/app.py", line 1950, in full_dispatch_request
    rv = self.dispatch_request()
  File "/home/snowsr/Projects/phonogenesis/pyscript/venv/lib/python3.8/site-packages/flask/app.py", line 1936, in dispatch_request
    return self.view_functions[rule.endpoint](**req.view_args)
  File "/home/snowsr/Projects/phonogenesis/pyscript/app/routes.py", line 37, in login
    return jsonify(result=session['user'])
  File "/home/snowsr/Projects/phonogenesis/pyscript/venv/lib/python3.8/site-packages/flask/json/__init__.py", line 370, in jsonify
    dumps(data, indent=indent, separators=separators) + "\n",
  File "/home/snowsr/Projects/phonogenesis/pyscript/venv/lib/python3.8/site-packages/flask/json/__init__.py", line 211, in dumps
    rv = _json.dumps(obj, **kwargs)
  File "/usr/lib/python3.8/json/__init__.py", line 234, in dumps
    return cls(
  File "/usr/lib/python3.8/json/encoder.py", line 199, in encode
    chunks = self.iterencode(o, _one_shot=True)
  File "/usr/lib/python3.8/json/encoder.py", line 257, in iterencode
    return _iterencode(o, 0)
  File "/home/snowsr/Projects/phonogenesis/pyscript/app/__init__.py", line 30, in default
    return super(PhonogenesisJSONEncoder, self).default(o)
  File "/home/snowsr/Projects/phonogenesis/pyscript/venv/lib/python3.8/site-packages/flask/json/__init__.py", line 100, in default
    return _json.JSONEncoder.default(self, o)
  File "/usr/lib/python3.8/json/encoder.py", line 179, in default
    raise TypeError(f'Object of type {o.__class__.__name__} '
TypeError: Object of type UserGroup is not JSON serializable
[2020-09-17 22:54:15] - ERROR - Request finalizing failed with an error while handling an error - app 1975@finalize_request
Traceback (most recent call last):
  File "/home/snowsr/Projects/phonogenesis/pyscript/venv/lib/python3.8/site-packages/flask/app.py", line 2447, in wsgi_app
    response = self.full_dispatch_request()
  File "/home/snowsr/Projects/phonogenesis/pyscript/venv/lib/python3.8/site-packages/flask/app.py", line 1952, in full_dispatch_request
    rv = self.handle_user_exception(e)
  File "/home/snowsr/Projects/phonogenesis/pyscript/venv/lib/python3.8/site-packages/flask_cors/extension.py", line 165, in wrapped_function
    return cors_after_request(app.make_response(f(*args, **kwargs)))
  File "/home/snowsr/Projects/phonogenesis/pyscript/venv/lib/python3.8/site-packages/flask/app.py", line 1821, in handle_user_exception
    reraise(exc_type, exc_value, tb)
  File "/home/snowsr/Projects/phonogenesis/pyscript/venv/lib/python3.8/site-packages/flask/_compat.py", line 39, in reraise
    raise value
  File "/home/snowsr/Projects/phonogenesis/pyscript/venv/lib/python3.8/site-packages/flask/app.py", line 1950, in full_dispatch_request
    rv = self.dispatch_request()
  File "/home/snowsr/Projects/phonogenesis/pyscript/venv/lib/python3.8/site-packages/flask/app.py", line 1936, in dispatch_request
    return self.view_functions[rule.endpoint](**req.view_args)
  File "/home/snowsr/Projects/phonogenesis/pyscript/app/routes.py", line 37, in login
    return jsonify(result=session['user'])
  File "/home/snowsr/Projects/phonogenesis/pyscript/venv/lib/python3.8/site-packages/flask/json/__init__.py", line 370, in jsonify
    dumps(data, indent=indent, separators=separators) + "\n",
  File "/home/snowsr/Projects/phonogenesis/pyscript/venv/lib/python3.8/site-packages/flask/json/__init__.py", line 211, in dumps
    rv = _json.dumps(obj, **kwargs)
  File "/usr/lib/python3.8/json/__init__.py", line 234, in dumps
    return cls(
  File "/usr/lib/python3.8/json/encoder.py", line 199, in encode
    chunks = self.iterencode(o, _one_shot=True)
  File "/usr/lib/python3.8/json/encoder.py", line 257, in iterencode
    return _iterencode(o, 0)
  File "/home/snowsr/Projects/phonogenesis/pyscript/app/__init__.py", line 30, in default
    return super(PhonogenesisJSONEncoder, self).default(o)
  File "/home/snowsr/Projects/phonogenesis/pyscript/venv/lib/python3.8/site-packages/flask/json/__init__.py", line 100, in default
    return _json.JSONEncoder.default(self, o)
  File "/usr/lib/python3.8/json/encoder.py", line 179, in default
    raise TypeError(f'Object of type {o.__class__.__name__} '
TypeError: Object of type UserGroup is not JSON serializable

During handling of the above exception, another exception occurred:

Traceback (most recent call last):
  File "/home/snowsr/Projects/phonogenesis/pyscript/venv/lib/python3.8/site-packages/flask/app.py", line 1970, in finalize_request
    response = self.process_response(response)
  File "/home/snowsr/Projects/phonogenesis/pyscript/venv/lib/python3.8/site-packages/flask/app.py", line 2269, in process_response
    self.session_interface.save_session(self, ctx.session, response)
  File "/home/snowsr/Projects/phonogenesis/pyscript/venv/lib/python3.8/site-packages/flask/sessions.py", line 378, in save_session
    val = self.get_signing_serializer(app).dumps(dict(session))
  File "/home/snowsr/Projects/phonogenesis/pyscript/venv/lib/python3.8/site-packages/itsdangerous/serializer.py", line 166, in dumps
    payload = want_bytes(self.dump_payload(obj))
  File "/home/snowsr/Projects/phonogenesis/pyscript/venv/lib/python3.8/site-packages/itsdangerous/url_safe.py", line 42, in dump_payload
    json = super(URLSafeSerializerMixin, self).dump_payload(obj)
  File "/home/snowsr/Projects/phonogenesis/pyscript/venv/lib/python3.8/site-packages/itsdangerous/serializer.py", line 133, in dump_payload
    return want_bytes(self.serializer.dumps(obj, **self.serializer_kwargs))
  File "/home/snowsr/Projects/phonogenesis/pyscript/venv/lib/python3.8/site-packages/flask/json/tag.py", line 305, in dumps
    return dumps(self.tag(value), separators=(",", ":"))
  File "/home/snowsr/Projects/phonogenesis/pyscript/venv/lib/python3.8/site-packages/flask/json/__init__.py", line 211, in dumps
    rv = _json.dumps(obj, **kwargs)
  File "/usr/lib/python3.8/json/__init__.py", line 234, in dumps
    return cls(
  File "/usr/lib/python3.8/json/encoder.py", line 199, in encode
    chunks = self.iterencode(o, _one_shot=True)
  File "/usr/lib/python3.8/json/encoder.py", line 257, in iterencode
    return _iterencode(o, 0)
  File "/home/snowsr/Projects/phonogenesis/pyscript/app/__init__.py", line 30, in default
    return super(PhonogenesisJSONEncoder, self).default(o)
  File "/home/snowsr/Projects/phonogenesis/pyscript/venv/lib/python3.8/site-packages/flask/json/__init__.py", line 100, in default
    return _json.JSONEncoder.default(self, o)
  File "/usr/lib/python3.8/json/encoder.py", line 179, in default
    raise TypeError(f'Object of type {o.__class__.__name__} '
TypeError: Object of type UserGroup is not JSON serializable
